Workbook
Name __1: #REF!
Name __1: #REF!
Name __1: #REF!
Name _2: #REF!
Name _2: #REF!
Name _2: #REF!
Name a: #REF!
Name a: #REF!
Name a: #REF!
Name Ahmed: #REF!
Name Ahmed: #REF!
Name Ahmed: #REF!
Name Ali: #REF!
Name Ali: #REF!
Name Ali: #REF!
Name B: #REF!
Name B: #REF!
Name B: #REF!
Name BlockWork: #REF!
Name BlockWork: #REF!
Name BlockWork: #REF!
Name Budget_code_Rev: #REF!
Name Budget_code_Rev: #REF!
Name Budget_code_Rev: #REF!
Name buyout: #REF!
Name buyout: #REF!
Name buyout: #REF!
Name Buyout_items: #REF!
Name Buyout_items: #REF!
Name Buyout_items: #REF!
Name ConcreteWork: #REF!
Name ConcreteWork: #REF!
Name ConcreteWork: #REF!
Name ConveyingSystems: #REF!
Name ConveyingSystems: #REF!
Name ConveyingSystems: #REF!
Name EarthWork: #REF!
Name EarthWork: #REF!
Name EarthWork: #REF!
Name ElectricalWork: #REF!
Name ElectricalWork: #REF!
Name ElectricalWork: #REF!
Name Finishing: #REF!
Name Finishing: #REF!
Name Finishing: #REF!
Name FireFighting: #REF!
Name FireFighting: #REF!
Name FireFighting: #REF!
Name Furniture: #REF!
Name Furniture: #REF!
Name Furniture: #REF!
Name HVACWork: #REF!
Name HVACWork: #REF!
Name HVACWork: #REF!
Name Insulation: #REF!
Name Insulation: #REF!
Name Insulation: #REF!
Name MetalWork: #REF!
Name MetalWork: #REF!
Name MetalWork: #REF!

Sheet Manual Manpower Database
C2: Manual Manpower Cost Database
C3: Non-Manual Staff Details | T3: Yearly Expenses Proportional in Terms of Basic Salary | X3: Monthly Expense in terms of Basic Salary | Z3: Fixed Yearly Payment | AE3: One time Payment in terms of Basic | AG3: Fixed One time Payment | AJ3: Monthly Expense of all Categories
C4: Type | D4: Portfolio | E4: Devision | F4: Sub-Division | G4: Organization Position | H4: No. | I4: Sum of Basic Salary | J4: Average of Basic Salary | K4: Max of Basic Salary | L4: Min of Basic Salary | M4: Max of Transport Allowance | N4: Min of Transport Allowance | O4: Min of Housing Allowance monthes | P4: Max of Housing Allowance monthes | Q4: Max of Food Allowance | R4: Min of Food Allowance | T4: Vacation Pay | U4: Bonus | V4: EOS Benefits | X4: GOSI | Z4: Air tickets | AA4: medical | AB4: Iqama Cost | AC4: Work Permits | AE4: Recruitment expenses | AG4: Relocation allowance | AH4: Visa cost | AJ4: Basic | AK4: Transportation | AL4: Housing | AM4: Food Allowance | AN4: Vacation Pay | AO4: Bonus | AP4: EOS Benefits | AQ4: GOSI | AR4: Air tickets | AS4: medical | AT4: Iqama Cost | AU4: Work Permits | AV4: Recruitment expenses | AW4: Relocation allowance | AX4: Visa cost | AY4: Total
C5: Manual | E5: Miscelainious | F5: Lab | G5: Assistant Lab Technician | H5: 6 | I5: 9540 | J5: 1590 | K5: 2290 | L5: 1000 | M5: 0 | N5: 0 | O5: 0 | P5: 0 | Q5: 150 | R5: 0 | T5: 1 | U5: 0 | V5: 0.5 | X5: 0.02 | Z5: =IF($J5>=5000,6000,3000) -> 3000 | AA5: =IF($J5>=5000,2650,500) -> 500 | AB5: 650 | AC5: 2500 | AE5: 0 | AG5: 300 | AH5: 2000 | AJ5: =J5 -> 1590 | AK5: =M5 -> 0 | AL5: =P5*J5/12 -> 0 | AM5: =Q5 -> 150 | AN5: =T5*J5/24 -> 66.25 | AO5: =U5*J5/12 -> 0 | AP5: =V5*J5/24 -> 33.125 | AQ5: =X5*(AJ5+AL5) -> 31.8 | AR5: =Z5/24 -> 125 | AS5: =AA5/12 -> 41.666667 | AT5: =AB5/12 -> 54.166667 | AU5: =AC5/12 -> 208.33333 | AV5: =AE5*AJ5/36 -> 0 | AW5: =AG5/36 -> 8.3333333 | AX5: =AH5/36 -> 55.555556 | AY5: =SUM(AJ5:AX5) -> 2364.2306
C6: Manual | E6: Miscelainious | F6: Store | G6: Assistant Store Keeper | H6: 10 | I6: 10837 | J6: 1083.7 | K6: 1365 | L6: 645 | M6: 0 | N6: 0 | O6: 0 | P6: 0 | Q6: 200 | R6: 150 | T6: 1 | U6: 0 | V6: 0.5 | X6: 0.02 | Z6: =IF($J6>=5000,6000,3000) -> 3000 | AA6: =IF($J6>=5000,2650,500) -> 500 | AB6: 650 | AC6: 2500 | AE6: 0 | AG6: 300 | AH6: 2000 | AJ6: =J6 -> 1083.7 | AK6: =M6 -> 0 | AL6: =P6*J6/12 -> 0 | AM6: =Q6 -> 200 | AN6: =T6*J6/24 -> 45.154167 | AO6: =U6*J6/12 -> 0 | AP6: =V6*J6/24 -> 22.577083 | AQ6: =X6*(AJ6+AL6) -> 21.674 | AR6: =Z6/24 -> 125 | AS6: =AA6/12 -> 41.666667 | AT6: =AB6/12 -> 54.166667 | AU6: =AC6/12 -> 208.33333 | AV6: =AE6*AJ6/36 -> 0 | AW6: =AG6/36 -> 8.3333333 | AX6: =AH6/36 -> 55.555556 | AY6: =SUM(AJ6:AX6) -> 1866.1608
C7: Manual | E7: Miscelainious | F7: Surveying | G7: Assistant Surveyor | H7: 18 | I7: 39070 | J7: 2170.5556 | K7: 3675 | L7: 900 | M7: 300 | N7: 0 | O7: 0 | P7: 0 | Q7: 150 | R7: 0 | T7: 1 | U7: 0 | V7: 0.5 | X7: 0.02 | Z7: =IF($J7>=5000,6000,3000) -> 3000 | AA7: =IF($J7>=5000,2650,500) -> 500 | AB7: 650 | AC7: 2500 | AE7: 0 | AG7: 300 | AH7: 2000 | AJ7: =J7 -> 2170.5556 | AK7: =M7 -> 300 | AL7: =P7*J7/12 -> 0 | AM7: =Q7 -> 150 | AN7: =T7*J7/24 -> 90.439815 | AO7: =U7*J7/12 -> 0 | AP7: =V7*J7/24 -> 45.219907 | AQ7: =X7*(AJ7+AL7) -> 43.411111 | AR7: =Z7/24 -> 125 | AS7: =AA7/12 -> 41.666667 | AT7: =AB7/12 -> 54.166667 | AU7: =AC7/12 -> 208.33333 | AV7: =AE7*AJ7/36 -> 0 | AW7: =AG7/36 -> 8.3333333 | AX7: =AH7/36 -> 55.555556 | AY7: =SUM(AJ7:AX7) -> 3292.6819
C8: Manual | D8: Batch pmalnts | E8: Equipment | F8: Equipment | G8: Batching Plant Maintenance Supervisor | H8: 5 | I8: 20000 | J8: 4000 | K8: 5000 | L8: 3000 | M8: 400 | N8: 0 | O8: 2 | P8: 2 | Q8: 0 | R8: 0 | T8: 1 | U8: 0 | V8: 0.5 | X8: 0.02 | Z8: =IF($J8>=5000,6000,3000) -> 3000 | AA8: =IF($J8>=5000,2650,500) -> 500 | AB8: 650 | AC8: 2500 | AE8: 0 | AG8: 300 | AH8: 2000 | AJ8: =J8 -> 4000 | AK8: =M8 -> 400 | AL8: =P8*J8/12 -> 666.66667 | AM8: =Q8 -> 0 | AN8: =T8*J8/24 -> 166.66667 | AO8: =U8*J8/12 -> 0 | AP8: =V8*J8/24 -> 83.333333 | AQ8: =X8*(AJ8+AL8) -> 93.333333 | AR8: =Z8/24 -> 125 | AS8: =AA8/12 -> 41.666667 | AT8: =AB8/12 -> 54.166667 | AU8: =AC8/12 -> 208.33333 | AV8: =AE8*AJ8/36 -> 0 | AW8: =AG8/36 -> 8.3333333 | AX8: =AH8/36 -> 55.555556 | AY8: =SUM(AJ8:AX8) -> 5903.0556
C9: Manual | D9: Cleaning Projects | E9: Work Shop | F9: Equipment | G9: Body Repairman | H9: 3 | I9: 3285 | J9: 1095 | K9: 1200 | L9: 1000 | M9: 0 | N9: 0 | O9: 0 | P9: 0 | Q9: 150 | R9: 0 | T9: 1 | U9: 0 | V9: 0.5 | X9: 0.02 | Z9: =IF($J9>=5000,6000,3000) -> 3000 | AA9: =IF($J9>=5000,2650,500) -> 500 | AB9: 650 | AC9: 2500 | AE9: 0 | AG9: 300 | AH9: 2000 | AJ9: =J9 -> 1095 | AK9: =M9 -> 0 | AL9: =P9*J9/12 -> 0 | AM9: =Q9 -> 150 | AN9: =T9*J9/24 -> 45.625 | AO9: =U9*J9/12 -> 0 | AP9: =V9*J9/24 -> 22.8125 | AQ9: =X9*(AJ9+AL9) -> 21.9 | AR9: =Z9/24 -> 125 | AS9: =AA9/12 -> 41.666667 | AT9: =AB9/12 -> 54.166667 | AU9: =AC9/12 -> 208.33333 | AV9: =AE9*AJ9/36 -> 0 | AW9: =AG9/36 -> 8.3333333 | AX9: =AH9/36 -> 55.555556 | AY9: =SUM(AJ9:AX9) -> 1828.3931
C10: Manual | D10: O&m | E10: Miscelainious | F10: Car Parking | G10: Car Parking Attendant | H10: 7 | I10: 4747 | J10: 678.14286 | K10: 847 | L10: 650 | M10: 0 | N10: 0 | O10: 0 | P10: 0 | Q10: 150 | R10: 150 | T10: 1 | U10: 0 | V10: 0.5 | X10: 0.02 | Z10: =IF($J10>=5000,6000,3000) -> 3000 | AA10: =IF($J10>=5000,2650,500) -> 500 | AB10: 650 | AC10: 2500 | AE10: 0 | AG10: 300 | AH10: 2000 | AJ10: =J10 -> 678.14286 | AK10: =M10 -> 0 | AL10: =P10*J10/12 -> 0 | AM10: =Q10 -> 150 | AN10: =T10*J10/24 -> 28.255952 | AO10: =U10*J10/12 -> 0 | AP10: =V10*J10/24 -> 14.127976 | AQ10: =X10*(AJ10+AL10) -> 13.562857 | AR10: =Z10/24 -> 125 | AS10: =AA10/12 -> 41.666667 | AT10: =AB10/12 -> 54.166667 | AU10: =AC10/12 -> 208.33333 | AV10: =AE10*AJ10/36 -> 0 | AW10: =AG10/36 -> 8.3333333 | AX10: =AH10/36 -> 55.555556 | AY10: =SUM(AJ10:AX10) -> 1377.1452
C11: Manual | E11: Finishing | F11: Concrete Form | G11: Carpenter Finishing | H11: 74 | I11: 72750 | J11: 983.10811 | K11: 1200 | L11: 850 | M11: 0 | N11: 0 | O11: 0 | P11: 0 | Q11: 150 | R11: 150 | T11: 1 | U11: 0 | V11: 0.5 | X11: 0.02 | Z11: =IF($J11>=5000,6000,3000) -> 3000 | AA11: =IF($J11>=5000,2650,500) -> 500 | AB11: 650 | AC11: 2500 | AE11: 0 | AG11: 300 | AH11: 2000 | AJ11: =J11 -> 983.10811 | AK11: =M11 -> 0 | AL11: =P11*J11/12 -> 0 | AM11: =Q11 -> 150 | AN11: =T11*J11/24 -> 40.962838 | AO11: =U11*J11/12 -> 0 | AP11: =V11*J11/24 -> 20.481419 | AQ11: =X11*(AJ11+AL11) -> 19.662162 | AR11: =Z11/24 -> 125 | AS11: =AA11/12 -> 41.666667 | AT11: =AB11/12 -> 54.166667 | AU11: =AC11/12 -> 208.33333 | AV11: =AE11*AJ11/36 -> 0 | AW11: =AG11/36 -> 8.3333333 | AX11: =AH11/36 -> 55.555556 | AY11: =SUM(AJ11:AX11) -> 1707.2701
C12: Manual | E12: Concrete | F12: Concrete Form | G12: Carpenter Shuttering | H12: 1181 | I12: 1055898 | J12: 894.07113 | K12: 1800 | L12: 200 | M12: 0 | N12: 0 | O12: 0 | P12: 0 | Q12: 250 | R12: 0 | T12: 1 | U12: 0 | V12: 0.5 | X12: 0.02 | Z12: =IF($J12>=5000,6000,3000) -> 3000 | AA12: =IF($J12>=5000,2650,500) -> 500 | AB12: 650 | AC12: 2500 | AE12: 0 | AG12: 300 | AH12: 2000 | AJ12: =J12 -> 894.07113 | AK12: =M12 -> 0 | AL12: =P12*J12/12 -> 0 | AM12: =Q12 -> 250 | AN12: =T12*J12/24 -> 37.252964 | AO12: =U12*J12/12 -> 0 | AP12: =V12*J12/24 -> 18.626482 | AQ12: =X12*(AJ12+AL12) -> 17.881423 | AR12: =Z12/24 -> 125 | AS12: =AA12/12 -> 41.666667 | AT12: =AB12/12 -> 54.166667 | AU12: =AC12/12 -> 208.33333 | AV12: =AE12*AJ12/36 -> 0 | AW12: =AG12/36 -> 8.3333333 | AX12: =AH12/36 -> 55.555556 | AY12: =SUM(AJ12:AX12) -> 1710.8875
C13: Manual | E13: IT | F13: Computers | G13: Computer Technician | H13: 7 | I13: 28850 | J13: 4121.4286 | K13: 5500 | L13: 2750 | M13: 400 | N13: 0 | O13: 0 | P13: 0 | Q13: 0 | R13: 0 | T13: 1 | U13: 0 | V13: 0.5 | X13: 0.02 | Z13: =IF($J13>=5000,6000,3000) -> 3000 | AA13: =IF($J13>=5000,2650,500) -> 500 | AB13: 650 | AC13: 2500 | AE13: 0 | AG13: 300 | AH13: 2000 | AJ13: =J13 -> 4121.4286 | AK13: =M13 -> 400 | AL13: =P13*J13/12 -> 0 | AM13: =Q13 -> 0 | AN13: =T13*J13/24 -> 171.72619 | AO13: =U13*J13/12 -> 0 | AP13: =V13*J13/24 -> 85.863095 | AQ13: =X13*(AJ13+AL13) -> 82.428571 | AR13: =Z13/24 -> 125 | AS13: =AA13/12 -> 41.666667 | AT13: =AB13/12 -> 54.166667 | AU13: =AC13/12 -> 208.33333 | AV13: =AE13*AJ13/36 -> 0 | AW13: =AG13/36 -> 8.3333333 | AX13: =AH13/36 -> 55.555556 | AY13: =SUM(AJ13:AX13) -> 5354.502
C14: Manual | E14: Miscelainious | F14: Kitchen | G14: Cook | H14: 28 | I14: 30540 | J14: 1090.7143 | K14: 2000 | L14: 400 | M14: 0 | N14: 0 | O14: 0 | P14: 0 | Q14: 150 | R14: 0 | T14: 1 | U14: 0 | V14: 0.5 | X14: 0.02 | Z14: =IF($J14>=5000,6000,3000) -> 3000 | AA14: =IF($J14>=5000,2650,500) -> 500 | AB14: 650 | AC14: 2500 | AE14: 0 | AG14: 300 | AH14: 2000 | AJ14: =J14 -> 1090.7143 | AK14: =M14 -> 0 | AL14: =P14*J14/12 -> 0 | AM14: =Q14 -> 150 | AN14: =T14*J14/24 -> 45.446429 | AO14: =U14*J14/12 -> 0 | AP14: =V14*J14/24 -> 22.723214 | AQ14: =X14*(AJ14+AL14) -> 21.814286 | AR14: =Z14/24 -> 125 | AS14: =AA14/12 -> 41.666667 | AT14: =AB14/12 -> 54.166667 | AU14: =AC14/12 -> 208.33333 | AV14: =AE14*AJ14/36 -> 0 | AW14: =AG14/36 -> 8.3333333 | AX14: =AH14/36 -> 55.555556 | AY14: =SUM(AJ14:AX14) -> 1823.7538
C15: Manual | E15: Equipment | F15: Equipment | G15: Crusher Operator | H15: 24 | I15: 26950 | J15: 1122.9167 | K15: 1400 | L15: 900 | M15: 0 | N15: 0 | O15: 0 | P15: 0 | Q15: 200 | R15: 150 | T15: 1 | U15: 0 | V15: 0.5 | X15: 0.02 | Z15: =IF($J15>=5000,6000,3000) -> 3000 | AA15: =IF($J15>=5000,2650,500) -> 500 | AB15: 650 | AC15: 2500 | AE15: 0 | AG15: 300 | AH15: 2000 | AJ15: =J15 -> 1122.9167 | AK15: =M15 -> 0 | AL15: =P15*J15/12 -> 0 | AM15: =Q15 -> 200 | AN15: =T15*J15/24 -> 46.788194 | AO15: =U15*J15/12 -> 0 | AP15: =V15*J15/24 -> 23.394097 | AQ15: =X15*(AJ15+AL15) -> 22.458333 | AR15: =Z15/24 -> 125 | AS15: =AA15/12 -> 41.666667 | AT15: =AB15/12 -> 54.166667 | AU15: =AC15/12 -> 208.33333 | AV15: =AE15*AJ15/36 -> 0 | AW15: =AG15/36 -> 8.3333333 | AX15: =AH15/36 -> 55.555556 | AY15: =SUM(AJ15:AX15) -> 1908.6128
C16: Manual | E16: Equipment | F16: Equipment | G16: Crusher Technician | H16: 3 | I16: 4000 | J16: 1333.3333 | K16: 1500 | L16: 1200 | M16: 0 | N16: 0 | O16: 0 | P16: 0 | Q16: 200 | R16: 150 | T16: 1 | U16: 0 | V16: 0.5 | X16: 0.02 | Z16: =IF($J16>=5000,6000,3000) -> 3000 | AA16: =IF($J16>=5000,2650,500) -> 500 | AB16: 650 | AC16: 2500 | AE16: 0 | AG16: 300 | AH16: 2000 | AJ16: =J16 -> 1333.3333 | AK16: =M16 -> 0 | AL16: =P16*J16/12 -> 0 | AM16: =Q16 -> 200 | AN16: =T16*J16/24 -> 55.555556 | AO16: =U16*J16/12 -> 0 | AP16: =V16*J16/24 -> 27.777778 | AQ16: =X16*(AJ16+AL16) -> 26.666667 | AR16: =Z16/24 -> 125 | AS16: =AA16/12 -> 41.666667 | AT16: =AB16/12 -> 54.166667 | AU16: =AC16/12 -> 208.33333 | AV16: =AE16*AJ16/36 -> 0 | AW16: =AG16/36 -> 8.3333333 | AX16: =AH16/36 -> 55.555556 | AY16: =SUM(AJ16:AX16) -> 2136.3889
C17: Manual | E17: Equipment | F17: Equipment | G17: Cutter | H17: 6 | I17: 3695 | J17: 615.83333 | K17: 660 | L17: 535 | M17: 0 | N17: 0 | O17: 0 | P17: 0 | Q17: 250 | R17: 250 | T17: 1 | U17: 0 | V17: 0.5 | X17: 0.02 | Z17: =IF($J17>=5000,6000,3000) -> 3000 | AA17: =IF($J17>=5000,2650,500) -> 500 | AB17: 650 | AC17: 2500 | AE17: 0 | AG17: 300 | AH17: 2000 | AJ17: =J17 -> 615.83333 | AK17: =M17 -> 0 | AL17: =P17*J17/12 -> 0 | AM17: =Q17 -> 250 | AN17: =T17*J17/24 -> 25.659722 | AO17: =U17*J17/12 -> 0 | AP17: =V17*J17/24 -> 12.829861 | AQ17: =X17*(AJ17+AL17) -> 12.316667 | AR17: =Z17/24 -> 125 | AS17: =AA17/12 -> 41.666667 | AT17: =AB17/12 -> 54.166667 | AU17: =AC17/12 -> 208.33333 | AV17: =AE17*AJ17/36 -> 0 | AW17: =AG17/36 -> 8.3333333 | AX17: =AH17/36 -> 55.555556 | AY17: =SUM(AJ17:AX17) -> 1409.6951
C18: Manual | E18: Equipment | F18: Equipment | G18: Denter | H18: 3 | I18: 3090 | J18: 1030 | K18: 1300 | L18: 690 | M18: 0 | N18: 0 | O18: 0 | P18: 0 | Q18: 150 | R18: 120 | T18: 1 | U18: 0 | V18: 0.5 | X18: 0.02 | Z18: =IF($J18>=5000,6000,3000) -> 3000 | AA18: =IF($J18>=5000,2650,500) -> 500 | AB18: 650 | AC18: 2500 | AE18: 0 | AG18: 300 | AH18: 2000 | AJ18: =J18 -> 1030 | AK18: =M18 -> 0 | AL18: =P18*J18/12 -> 0 | AM18: =Q18 -> 150 | AN18: =T18*J18/24 -> 42.916667 | AO18: =U18*J18/12 -> 0 | AP18: =V18*J18/24 -> 21.458333 | AQ18: =X18*(AJ18+AL18) -> 20.6 | AR18: =Z18/24 -> 125 | AS18: =AA18/12 -> 41.666667 | AT18: =AB18/12 -> 54.166667 | AU18: =AC18/12 -> 208.33333 | AV18: =AE18*AJ18/36 -> 0 | AW18: =AG18/36 -> 8.3333333 | AX18: =AH18/36 -> 55.555556 | AY18: =SUM(AJ18:AX18) -> 1758.0306
C19: Manual | E19: Equipment | F19: Equipment | G19: Diesel Mechanic | H19: 1 | I19: 1200 | J19: 1200 | K19: 1200 | L19: 1200 | M19: 0 | N19: 0 | O19: 0 | P19: 0 | Q19: 150 | R19: 150 | T19: 1 | U19: 0 | V19: 0.5 | X19: 0.02 | Z19: =IF($J19>=5000,6000,3000) -> 3000 | AA19: =IF($J19>=5000,2650,500) -> 500 | AB19: 650 | AC19: 2500 | AE19: 0 | AG19: 300 | AH19: 2000 | AJ19: =J19 -> 1200 | AK19: =M19 -> 0 | AL19: =P19*J19/12 -> 0 | AM19: =Q19 -> 150 | AN19: =T19*J19/24 -> 50 | AO19: =U19*J19/12 -> 0 | AP19: =V19*J19/24 -> 25 | AQ19: =X19*(AJ19+AL19) -> 24 | AR19: =Z19/24 -> 125 | AS19: =AA19/12 -> 41.666667 | AT19: =AB19/12 -> 54.166667 | AU19: =AC19/12 -> 208.33333 | AV19: =AE19*AJ19/36 -> 0 | AW19: =AG19/36 -> 8.3333333 | AX19: =AH19/36 -> 55.555556 | AY19: =SUM(AJ19:AX19) -> 1942.0556
C20: Manual | E20: Miscelainious | F20: Drivers | G20: Driver Ambulance | H20: 8 | I20: 8050 | J20: 1006.25 | K20: 1350 | L20: 800 | M20: 0 | N20: 0 | O20: 0 | P20: 0 | Q20: 200 | R20: 150 | T20: 1 | U20: 0 | V20: 0.5 | X20: 0.02 | Z20: =IF($J20>=5000,6000,3000) -> 3000 | AA20: =IF($J20>=5000,2650,500) -> 500 | AB20: 650 | AC20: 2500 | AE20: 0 | AG20: 300 | AH20: 2000 | AJ20: =J20 -> 1006.25 | AK20: =M20 -> 0 | AL20: =P20*J20/12 -> 0 | AM20: =Q20 -> 200 | AN20: =T20*J20/24 -> 41.927083 | AO20: =U20*J20/12 -> 0 | AP20: =V20*J20/24 -> 20.963542 | AQ20: =X20*(AJ20+AL20) -> 20.125 | AR20: =Z20/24 -> 125 | AS20: =AA20/12 -> 41.666667 | AT20: =AB20/12 -> 54.166667 | AU20: =AC20/12 -> 208.33333 | AV20: =AE20*AJ20/36 -> 0 | AW20: =AG20/36 -> 8.3333333 | AX20: =AH20/36 -> 55.555556 | AY20: =SUM(AJ20:AX20) -> 1782.3212
C21: Manual | E21: Miscelainious | F21: Drivers | G21: Driver Concrete Mixer | H21: 5 | I21: 5900 | J21: 1180 | K21: 1300 | L21: 1100 | M21: 0 | N21: 0 | O21: 0 | P21: 0 | Q21: 150 | R21: 150 | T21: 1 | U21: 0 | V21: 0.5 | X21: 0.02 | Z21: =IF($J21>=5000,6000,3000) -> 3000 | AA21: =IF($J21>=5000,2650,500) -> 500 | AB21: 650 | AC21: 2500 | AE21: 0 | AG21: 300 | AH21: 2000 | AJ21: =J21 -> 1180 | AK21: =M21 -> 0 | AL21: =P21*J21/12 -> 0 | AM21: =Q21 -> 150 | AN21: =T21*J21/24 -> 49.166667 | AO21: =U21*J21/12 -> 0 | AP21: =V21*J21/24 -> 24.583333 | AQ21: =X21*(AJ21+AL21) -> 23.6 | AR21: =Z21/24 -> 125 | AS21: =AA21/12 -> 41.666667 | AT21: =AB21/12 -> 54.166667 | AU21: =AC21/12 -> 208.33333 | AV21: =AE21*AJ21/36 -> 0 | AW21: =AG21/36 -> 8.3333333 | AX21: =AH21/36 -> 55.555556 | AY21: =SUM(AJ21:AX21) -> 1920.4056
C22: Manual | E22: Miscelainious | F22: Drivers | G22: Driver Dump Truck | H22: 2 | I22: 2350 | J22: 1175 | K22: 1500 | L22: 850 | M22: 0 | N22: 0 | O22: 0 | P22: 0 | Q22: 150 | R22: 150 | T22: 1 | U22: 0 | V22: 0.5 | X22: 0.02 | Z22: =IF($J22>=5000,6000,3000) -> 3000 | AA22: =IF($J22>=5000,2650,500) -> 500 | AB22: 650 | AC22: 2500 | AE22: 0 | AG22: 300 | AH22: 2000 | AJ22: =J22 -> 1175 | AK22: =M22 -> 0 | AL22: =P22*J22/12 -> 0 | AM22: =Q22 -> 150 | AN22: =T22*J22/24 -> 48.958333 | AO22: =U22*J22/12 -> 0 | AP22: =V22*J22/24 -> 24.479167 | AQ22: =X22*(AJ22+AL22) -> 23.5 | AR22: =Z22/24 -> 125 | AS22: =AA22/12 -> 41.666667 | AT22: =AB22/12 -> 54.166667 | AU22: =AC22/12 -> 208.33333 | AV22: =AE22*AJ22/36 -> 0 | AW22: =AG22/36 -> 8.3333333 | AX22: =AH22/36 -> 55.555556 | AY22: =SUM(AJ22:AX22) -> 1914.9931
... C29: Manual | E29: HVAC | F29: HVAC | G29: Duct Technician | H29: 5 | I29: 5500 | J29: 1100 | K29: 1100 | L29: 1100 | M29: 0 | N29: 0 | O29: 0 | P29: 0 | Q29: 150 | R29: 150 | T29: 1 | U29: 0 | V29: 0.5 | X29: 0.02 | Z29: =IF($J29>=5000,6000,3000) -> 3000 | AA29: =IF($J29>=5000,2650,500) -> 500 | AB29: 650 | AC29: 2500 | AE29: 0 | AG29: 300 | AH29: 2000 | AJ29: =J29 -> 1100 | AK29: =M29 -> 0 | AL29: =P29*J29/12 -> 0 | AM29: =Q29 -> 150 | AN29: =T29*J29/24 -> 45.833333 | AO29: =U29*J29/12 -> 0 | AP29: =V29*J29/24 -> 22.916667 | AQ29: =X29*(AJ29+AL29) -> 22 | AR29: =Z29/24 -> 125 | AS29: =AA29/12 -> 41.666667 | AT29: =AB29/12 -> 54.166667 | AU29: =AC29/12 -> 208.33333 | AV29: =AE29*AJ29/36 -> 0 | AW29: =AG29/36 -> 8.3333333 | AX29: =AH29/36 -> 55.555556 | AY29: =SUM(AJ29:AX29) -> 1833.8056
C30: Manual | E30: Electrical | F30: Electrical | G30: Electrician | H30: 248 | I30: 286891 | J30: 1156.8185 | K30: 4500 | L30: 400 | M30: 300 | N30: 0 | Q30: 250 | R30: 0 | T30: 1 | U30: 0 | V30: 0.5 | X30: 0.02 | Z30: =IF($J30>=5000,6000,3000) -> 3000 | AA30: =IF($J30>=5000,2650,500) -> 500 | AB30: 650 | AC30: 2500 | AE30: 0 | AG30: 300 | AH30: 2000 | AJ30: =J30 -> 1156.8185 | AK30: =M30 -> 300 | AL30: =P30*J30/12 -> 0 | AM30: =Q30 -> 250 | AN30: =T30*J30/24 -> 48.200773 | AO30: =U30*J30/12 -> 0 | AP30: =V30*J30/24 -> 24.100386 | AQ30: =X30*(AJ30+AL30) -> 23.136371 | AR30: =Z30/24 -> 125 | AS30: =AA30/12 -> 41.666667 | AT30: =AB30/12 -> 54.166667 | AU30: =AC30/12 -> 208.33333 | AV30: =AE30*AJ30/36 -> 0 | AW30: =AG30/36 -> 8.3333333 | AX30: =AH30/36 -> 55.555556 | AY30: =SUM(AJ30:AX30) -> 2295.3116
C31: Manual | E31: Foremans | F31: Forman | G31: Foreman | H31: 221 | I31: 586714 | J31: 2654.8145 | K31: 14000 | L31: 200 | M31: 500 | N31: 0 | O31: 2 | P31: 3 | Q31: 250 | R31: 0 | T31: 1 | U31: 0 | V31: 0.5 | X31: 0.02 | Z31: =IF($J31>=5000,6000,3000) -> 3000 | AA31: =IF($J31>=5000,2650,500) -> 500 | AB31: 650 | AC31: 2500 | AE31: 0 | AG31: 300 | AH31: 2000 | AJ31: =J31 -> 2654.8145 | AK31: =M31 -> 500 | AL31: =P31*J31/12 -> 663.70362 | AM31: =Q31 -> 250 | AN31: =T31*J31/24 -> 110.61727 | AO31: =U31*J31/12 -> 0 | AP31: =V31*J31/24 -> 55.308635 | AQ31: =X31*(AJ31+AL31) -> 66.370362 | AR31: =Z31/24 -> 125 | AS31: =AA31/12 -> 41.666667 | AT31: =AB31/12 -> 54.166667 | AU31: =AC31/12 -> 208.33333 | AV31: =AE31*AJ31/36 -> 0 | AW31: =AG31/36 -> 8.3333333 | AX31: =AH31/36 -> 55.555556 | AY31: =SUM(AJ31:AX31) -> 4793.8699
C32: Manual | E32: Asphalt Plant | F32: Asphalt Plant | G32: Foreman Asphalt Plant | H32: 3 | I32: 9850 | J32: 3283.3333 | K32: 4200 | L32: 1650 | M32: 0 | N32: 0 | O32: 0 | P32: 0 | Q32: 150 | R32: 0 | T32: 1 | U32: 0 | V32: 0.5 | X32: 0.02 | Z32: =IF($J32>=5000,6000,3000) -> 3000 | AA32: =IF($J32>=5000,2650,500) -> 500 | AB32: 650 | AC32: 2500 | AE32: 0 | AG32: 300 | AH32: 2000 | AJ32: =J32 -> 3283.3333 | AK32: =M32 -> 0 | AL32: =P32*J32/12 -> 0 | AM32: =Q32 -> 150 | AN32: =T32*J32/24 -> 136.80556 | AO32: =U32*J32/12 -> 0 | AP32: =V32*J32/24 -> 68.402778 | AQ32: =X32*(AJ32+AL32) -> 65.666667 | AR32: =Z32/24 -> 125 | AS32: =AA32/12 -> 41.666667 | AT32: =AB32/12 -> 54.166667 | AU32: =AC32/12 -> 208.33333 | AV32: =AE32*AJ32/36 -> 0 | AW32: =AG32/36 -> 8.3333333 | AX32: =AH32/36 -> 55.555556 | AY32: =SUM(AJ32:AX32) -> 4197.2639
C33: Manual | E33: Supervision | F33: Foremans | G33: Foreman Assistant | H33: 10 | I33: 28100 | J33: 2810 | K33: 3200 | L33: 500 | M33: 300 | N33: 0 | O33: 0 | P33: 0 | Q33: 150 | R33: 0 | T33: 1 | U33: 0 | V33: 0.5 | X33: 0.02 | Z33: =IF($J33>=5000,6000,3000) -> 3000 | AA33: =IF($J33>=5000,2650,500) -> 500 | AB33: 650 | AC33: 2500 | AE33: 0 | AG33: 300 | AH33: 2000 | AJ33: =J33 -> 2810 | AK33: =M33 -> 300 | AL33: =P33*J33/12 -> 0 | AM33: =Q33 -> 150 | AN33: =T33*J33/24 -> 117.08333 | AO33: =U33*J33/12 -> 0 | AP33: =V33*J33/24 -> 58.541667 | AQ33: =X33*(AJ33+AL33) -> 56.2 | AR33: =Z33/24 -> 125 | AS33: =AA33/12 -> 41.666667 | AT33: =AB33/12 -> 54.166667 | AU33: =AC33/12 -> 208.33333 | AV33: =AE33*AJ33/36 -> 0 | AW33: =AG33/36 -> 8.3333333 | AX33: =AH33/36 -> 55.555556 | AY33: =SUM(AJ33:AX33) -> 3984.8806
C34: Manual | E34: Miscelainious | F34: Camp | G34: Foreman Camp | H34: 11 | I34: 12650 | J34: 1150 | K34: 1400 | L34: 1000 | M34: 0 | N34: 0 | O34: 0 | P34: 0 | Q34: 150 | R34: 150 | T34: 1 | U34: 0 | V34: 0.5 | X34: 0.02 | Z34: =IF($J34>=5000,6000,3000) -> 3000 | AA34: =IF($J34>=5000,2650,500) -> 500 | AB34: 650 | AC34: 2500 | AE34: 0 | AG34: 300 | AH34: 2000 | AJ34: =J34 -> 1150 | AK34: =M34 -> 0 | AL34: =P34*J34/12 -> 0 | AM34: =Q34 -> 150 | AN34: =T34*J34/24 -> 47.916667 | AO34: =U34*J34/12 -> 0 | AP34: =V34*J34/24 -> 23.958333 | AQ34: =X34*(AJ34+AL34) -> 23 | AR34: =Z34/24 -> 125 | AS34: =AA34/12 -> 41.666667 | AT34: =AB34/12 -> 54.166667 | AU34: =AC34/12 -> 208.33333 | AV34: =AE34*AJ34/36 -> 0 | AW34: =AG34/36 -> 8.3333333 | AX34: =AH34/36 -> 55.555556 | AY34: =SUM(AJ34:AX34) -> 1887.9306
C35: Manual | E35: Concrete | F35: Concrete Form | G35: Foreman Carpenter | H35: 15 | I35: 43593 | J35: 2906.2 | K35: 3600 | L35: 1418 | M35: 0 | N35: 0 | O35: 0 | P35: 0 | Q35: 250 | R35: 0 | T35: 1 | U35: 0 | V35: 0.5 | X35: 0.02 | Z35: =IF($J35>=5000,6000,3000) -> 3000 | AA35: =IF($J35>=5000,2650,500) -> 500 | AB35: 650 | AC35: 2500 | AE35: 0 | AG35: 300 | AH35: 2000 | AJ35: =J35 -> 2906.2 | AK35: =M35 -> 0 | AL35: =P35*J35/12 -> 0 | AM35: =Q35 -> 250 | AN35: =T35*J35/24 -> 121.09167 | AO35: =U35*J35/12 -> 0 | AP35: =V35*J35/24 -> 60.545833 | AQ35: =X35*(AJ35+AL35) -> 58.124 | AR35: =Z35/24 -> 125 | AS35: =AA35/12 -> 41.666667 | AT35: =AB35/12 -> 54.166667 | AU35: =AC35/12 -> 208.33333 | AV35: =AE35*AJ35/36 -> 0 | AW35: =AG35/36 -> 8.3333333 | AX35: =AH35/36 -> 55.555556 | AY35: =SUM(AJ35:AX35) -> 3889.0171
C36: Manual | E36: Concrete | F36: General | G36: Foreman Civil | H36: 153 | I36: 488789 | J36: 3194.6993 | K36: 5000 | L36: 1400 | M36: 400 | N36: 0 | O36: 2 | P36: 3 | Q36: 150 | R36: 0 | T36: 1 | U36: 0 | V36: 0.5 | X36: 0.02 | Z36: =IF($J36>=5000,6000,3000) -> 3000 | AA36: =IF($J36>=5000,2650,500) -> 500 | AB36: 650 | AC36: 2500 | AE36: 0 | AG36: 300 | AH36: 2000 | AJ36: =J36 -> 3194.6993 | AK36: =M36 -> 400 | AL36: =P36*J36/12 -> 798.67484 | AM36: =Q36 -> 150 | AN36: =T36*J36/24 -> 133.11247 | AO36: =U36*J36/12 -> 0 | AP36: =V36*J36/24 -> 66.556236 | AQ36: =X36*(AJ36+AL36) -> 79.867484 | AR36: =Z36/24 -> 125 | AS36: =AA36/12 -> 41.666667 | AT36: =AB36/12 -> 54.166667 | AU36: =AC36/12 -> 208.33333 | AV36: =AE36*AJ36/36 -> 0 | AW36: =AG36/36 -> 8.3333333 | AX36: =AH36/36 -> 55.555556 | AY36: =SUM(AJ36:AX36) -> 5315.9659
C37: Manual | E37: Cleaning | F37: Cleaning | G37: Foreman Cleaning | H37: 202 | I37: 232429 | J37: 1150.6386 | K37: 5500 | L37: 200 | M37: 500 | N37: 0 | O37: 2 | P37: 2 | Q37: 250 | R37: 0 | T37: 1 | U37: 0 | V37: 0.5 | X37: 0.02 | Z37: =IF($J37>=5000,6000,3000) -> 3000 | AA37: =IF($J37>=5000,2650,500) -> 500 | AB37: 650 | AC37: 2500 | AE37: 0 | AG37: 300 | AH37: 2000 | AJ37: =J37 -> 1150.6386 | AK37: =M37 -> 500 | AL37: =P37*J37/12 -> 191.7731 | AM37: =Q37 -> 250 | AN37: =T37*J37/24 -> 47.943276 | AO37: =U37*J37/12 -> 0 | AP37: =V37*J37/24 -> 23.971638 | AQ37: =X37*(AJ37+AL37) -> 26.848234 | AR37: =Z37/24 -> 125 | AS37: =AA37/12 -> 41.666667 | AT37: =AB37/12 -> 54.166667 | AU37: =AC37/12 -> 208.33333 | AV37: =AE37*AJ37/36 -> 0 | AW37: =AG37/36 -> 8.3333333 | AX37: =AH37/36 -> 55.555556 | AY37: =SUM(AJ37:AX37) -> 2684.2304
C38: Manual | E38: Crushing Plant | F38: Crushing Plant | G38: Foreman Crusher | H38: 2 | I38: 4500 | J38: 2250 | K38: 2500 | L38: 2000 | M38: 0 | N38: 0 | O38: 0 | P38: 0 | Q38: 200 | R38: 0 | T38: 1 | U38: 0 | V38: 0.5 | X38: 0.02 | Z38: =IF($J38>=5000,6000,3000) -> 3000 | AA38: =IF($J38>=5000,2650,500) -> 500 | AB38: 650 | AC38: 2500 | AE38: 0 | AG38: 300 | AH38: 2000 | AJ38: =J38 -> 2250 | AK38: =M38 -> 0 | AL38: =P38*J38/12 -> 0 | AM38: =Q38 -> 200 | AN38: =T38*J38/24 -> 93.75 | AO38: =U38*J38/12 -> 0 | AP38: =V38*J38/24 -> 46.875 | AQ38: =X38*(AJ38+AL38) -> 45 | AR38: =Z38/24 -> 125 | AS38: =AA38/12 -> 41.666667 | AT38: =AB38/12 -> 54.166667 | AU38: =AC38/12 -> 208.33333 | AV38: =AE38*AJ38/36 -> 0 | AW38: =AG38/36 -> 8.3333333 | AX38: =AH38/36 -> 55.555556 | AY38: =SUM(AJ38:AX38) -> 3128.6806
C39: Manual | E39: HVAC | F39: HVAC | G39: Foreman Ducting | H39: 6 | I39: 16875 | J39: 2812.5 | K39: 3200 | L39: 2300 | M39: 0 | N39: 0 | O39: 0 | P39: 0 | Q39: 0 | R39: 0 | T39: 1 | U39: 0 | V39: 0.5 | X39: 0.02 | Z39: =IF($J39>=5000,6000,3000) -> 3000 | AA39: =IF($J39>=5000,2650,500) -> 500 | AB39: 650 | AC39: 2500 | AE39: 0 | AG39: 300 | AH39: 2000 | AJ39: =J39 -> 2812.5 | AK39: =M39 -> 0 | AL39: =P39*J39/12 -> 0 | AM39: =Q39 -> 0 | AN39: =T39*J39/24 -> 117.1875 | AO39: =U39*J39/12 -> 0 | AP39: =V39*J39/24 -> 58.59375 | AQ39: =X39*(AJ39+AL39) -> 56.25 | AR39: =Z39/24 -> 125 | AS39: =AA39/12 -> 41.666667 | AT39: =AB39/12 -> 54.166667 | AU39: =AC39/12 -> 208.33333 | AV39: =AE39*AJ39/36 -> 0 | AW39: =AG39/36 -> 8.3333333 | AX39: =AH39/36 -> 55.555556 | AY39: =SUM(AJ39:AX39) -> 3537.5868
C40: Manual | E40: Earth Work | F40: Earth Work | G40: Foreman Earthwork | H40: 2 | I40: 5500 | J40: 2750 | K40: 3000 | L40: 2500 | M40: 0 | N40: 0 | O40: 0 | P40: 0 | Q40: 0 | R40: 0 | T40: 1 | U40: 0 | V40: 0.5 | X40: 0.02 | Z40: =IF($J40>=5000,6000,3000) -> 3000 | AA40: =IF($J40>=5000,2650,500) -> 500 | AB40: 650 | AC40: 2500 | AE40: 0 | AG40: 300 | AH40: 2000 | AJ40: =J40 -> 2750 | AK40: =M40 -> 0 | AL40: =P40*J40/12 -> 0 | AM40: =Q40 -> 0 | AN40: =T40*J40/24 -> 114.58333 | AO40: =U40*J40/12 -> 0 | AP40: =V40*J40/24 -> 57.291667 | AQ40: =X40*(AJ40+AL40) -> 55 | AR40: =Z40/24 -> 125 | AS40: =AA40/12 -> 41.666667 | AT40: =AB40/12 -> 54.166667 | AU40: =AC40/12 -> 208.33333 | AV40: =AE40*AJ40/36 -> 0 | AW40: =AG40/36 -> 8.3333333 | AX40: =AH40/36 -> 55.555556 | AY40: =SUM(AJ40:AX40) -> 3469.9306
C41: Manual | E41: Electrical | F41: Electrical | G41: Foreman Electrical | H41: 50 | I41: 143791 | J41: 2875.82 | K41: 4000 | L41: 1386 | M41: 400 | N41: 0 | O41: 2 | P41: 2 | Q41: 250 | R41: 0 | T41: 1 | U41: 0 | V41: 0.5 | X41: 0.02 | Z41: =IF($J41>=5000,6000,3000) -> 3000 | AA41: =IF($J41>=5000,2650,500) -> 500 | AB41: 650 | AC41: 2500 | AE41: 0 | AG41: 300 | AH41: 2000 | AJ41: =J41 -> 2875.82 | AK41: =M41 -> 400 | AL41: =P41*J41/12 -> 479.30333 | AM41: =Q41 -> 250 | AN41: =T41*J41/24 -> 119.82583 | AO41: =U41*J41/12 -> 0 | AP41: =V41*J41/24 -> 59.912917 | AQ41: =X41*(AJ41+AL41) -> 67.102467 | AR41: =Z41/24 -> 125 | AS41: =AA41/12 -> 41.666667 | AT41: =AB41/12 -> 54.166667 | AU41: =AC41/12 -> 208.33333 | AV41: =AE41*AJ41/36 -> 0 | AW41: =AG41/36 -> 8.3333333 | AX41: =AH41/36 -> 55.555556 | AY41: =SUM(AJ41:AX41) -> 4745.0201
C42: Manual | E42: Equipment | F42: Equipment | G42: Foreman EMD | H42: 2 | I42: 4500 | J42: 2250 | K42: 2500 | L42: 2000 | M42: 0 | N42: 0 | O42: 0 | P42: 0 | Q42: 150 | R42: 0 | T42: 1 | U42: 0 | V42: 0.5 | X42: 0.02 | Z42: =IF($J42>=5000,6000,3000) -> 3000 | AA42: =IF($J42>=5000,2650,500) -> 500 | AB42: 650 | AC42: 2500 | AE42: 0 | AG42: 300 | AH42: 2000 | AJ42: =J42 -> 2250 | AK42: =M42 -> 0 | AL42: =P42*J42/12 -> 0 | AM42: =Q42 -> 150 | AN42: =T42*J42/24 -> 93.75 | AO42: =U42*J42/12 -> 0 | AP42: =V42*J42/24 -> 46.875 | AQ42: =X42*(AJ42+AL42) -> 45 | AR42: =Z42/24 -> 125 | AS42: =AA42/12 -> 41.666667 | AT42: =AB42/12 -> 54.166667 | AU42: =AC42/12 -> 208.33333 | AV42: =AE42*AJ42/36 -> 0 | AW42: =AG42/36 -> 8.3333333 | AX42: =AH42/36 -> 55.555556 | AY42: =SUM(AJ42:AX42) -> 3078.6806
... C46: Manual | E46: Work Shop | F46: Maintenance | G46: Foreman Mechanical | H46: 25 | I46: 82062 | J46: 3282.48 | K46: 5500 | L46: 2200 | M46: 300 | N46: 0 | O46: 2 | P46: 2 | Q46: 150 | R46: 0 | T46: 1 | U46: 0 | V46: 0.5 | X46: 0.02 | Z46: =IF($J46>=5000,6000,3000) -> 3000 | AA46: =IF($J46>=5000,2650,500) -> 500 | AB46: 650 | AC46: 2500 | AE46: 0 | AG46: 300 | AH46: 2000 | AJ46: =J46 -> 3282.48 | AK46: =M46 -> 300 | AL46: =P46*J46/12 -> 547.08 | AM46: =Q46 -> 150 | AN46: =T46*J46/24 -> 136.77 | AO46: =U46*J46/12 -> 0 | AP46: =V46*J46/24 -> 68.385 | AQ46: =X46*(AJ46+AL46) -> 76.5912 | AR46: =Z46/24 -> 125 | AS46: =AA46/12 -> 41.666667 | AT46: =AB46/12 -> 54.166667 | AU46: =AC46/12 -> 208.33333 | AV46: =AE46*AJ46/36 -> 0 | AW46: =AG46/36 -> 8.3333333 | AX46: =AH46/36 -> 55.555556 | AY46: =SUM(AJ46:AX46) -> 5054.3618
C47: Manual | G47: Foreman Operations | H47: 4 | I47: 7764 | J47: 1941 | K47: 2100 | L47: 1850 | M47: 0 | N47: 0 | O47: 0 | P47: 0 | Q47: 250 | R47: 0 | T47: 1 | U47: 0 | V47: 0.5 | X47: 0.02 | Z47: =IF($J47>=5000,6000,3000) -> 3000 | AA47: =IF($J47>=5000,2650,500) -> 500 | AB47: 650 | AC47: 2500 | AE47: 0 | AG47: 300 | AH47: 2000 | AJ47: =J47 -> 1941 | AK47: =M47 -> 0 | AL47: =P47*J47/12 -> 0 | AM47: =Q47 -> 250 | AN47: =T47*J47/24 -> 80.875 | AO47: =U47*J47/12 -> 0 | AP47: =V47*J47/24 -> 40.4375 | AQ47: =X47*(AJ47+AL47) -> 38.82 | AR47: =Z47/24 -> 125 | AS47: =AA47/12 -> 41.666667 | AT47: =AB47/12 -> 54.166667 | AU47: =AC47/12 -> 208.33333 | AV47: =AE47*AJ47/36 -> 0 | AW47: =AG47/36 -> 8.3333333 | AX47: =AH47/36 -> 55.555556 | AY47: =SUM(AJ47:AX47) -> 2844.1881
C48: Manual | E48: Finishing | F48: Painting | G48: Foreman Painter | H48: 5 | I48: 15545 | J48: 3109 | K48: 3500 | L48: 2800 | M48: 0 | N48: 0 | O48: 2 | P48: 2 | Q48: 0 | R48: 0 | T48: 1 | U48: 0 | V48: 0.5 | X48: 0.02 | Z48: =IF($J48>=5000,6000,3000) -> 3000 | AA48: =IF($J48>=5000,2650,500) -> 500 | AB48: 650 | AC48: 2500 | AE48: 0 | AG48: 300 | AH48: 2000 | AJ48: =J48 -> 3109 | AK48: =M48 -> 0 | AL48: =P48*J48/12 -> 518.16667 | AM48: =Q48 -> 0 | AN48: =T48*J48/24 -> 129.54167 | AO48: =U48*J48/12 -> 0 | AP48: =V48*J48/24 -> 64.770833 | AQ48: =X48*(AJ48+AL48) -> 72.543333 | AR48: =Z48/24 -> 125 | AS48: =AA48/12 -> 41.666667 | AT48: =AB48/12 -> 54.166667 | AU48: =AC48/12 -> 208.33333 | AV48: =AE48*AJ48/36 -> 0 | AW48: =AG48/36 -> 8.3333333 | AX48: =AH48/36 -> 55.555556 | AY48: =SUM(AJ48:AX48) -> 4387.0781
C49: Manual | E49: Plumbing | F49: Sewage | G49: Foreman Piping | H49: 10 | I49: 30300 | J49: 3030 | K49: 4500 | L49: 2200 | M49: 0 | N49: 0 | O49: 2 | P49: 2 | Q49: 150 | R49: 0 | T49: 1 | U49: 0 | V49: 0.5 | X49: 0.02 | Z49: =IF($J49>=5000,6000,3000) -> 3000 | AA49: =IF($J49>=5000,2650,500) -> 500 | AB49: 650 | AC49: 2500 | AE49: 0 | AG49: 300 | AH49: 2000 | AJ49: =J49 -> 3030 | AK49: =M49 -> 0 | AL49: =P49*J49/12 -> 505 | AM49: =Q49 -> 150 | AN49: =T49*J49/24 -> 126.25 | AO49: =U49*J49/12 -> 0 | AP49: =V49*J49/24 -> 63.125 | AQ49: =X49*(AJ49+AL49) -> 70.7 | AR49: =Z49/24 -> 125 | AS49: =AA49/12 -> 41.666667 | AT49: =AB49/12 -> 54.166667 | AU49: =AC49/12 -> 208.33333 | AV49: =AE49*AJ49/36 -> 0 | AW49: =AG49/36 -> 8.3333333 | AX49: =AH49/36 -> 55.555556 | AY49: =SUM(AJ49:AX49) -> 4438.1306
C50: Manual | E50: Equipment | F50: Equipment | G50: Foreman Plant Equipment | H50: 3 | I50: 12364 | J50: 4121.3333 | K50: 6064 | L50: 2900 | M50: 0 | N50: 0 | O50: 2 | P50: 2 | Q50: 0 | R50: 0 | T50: 1 | U50: 0 | V50: 0.5 | X50: 0.02 | Z50: =IF($J50>=5000,6000,3000) -> 3000 | AA50: =IF($J50>=5000,2650,500) -> 500 | AB50: 650 | AC50: 2500 | AE50: 0 | AG50: 300 | AH50: 2000 | AJ50: =J50 -> 4121.3333 | AK50: =M50 -> 0 | AL50: =P50*J50/12 -> 686.88889 | AM50: =Q50 -> 0 | AN50: =T50*J50/24 -> 171.72222 | AO50: =U50*J50/12 -> 0 | AP50: =V50*J50/24 -> 85.861111 | AQ50: =X50*(AJ50+AL50) -> 96.164444 | AR50: =Z50/24 -> 125 | AS50: =AA50/12 -> 41.666667 | AT50: =AB50/12 -> 54.166667 | AU50: =AC50/12 -> 208.33333 | AV50: =AE50*AJ50/36 -> 0 | AW50: =AG50/36 -> 8.3333333 | AX50: =AH50/36 -> 55.555556 | AY50: =SUM(AJ50:AX50) -> 5655.0256
...

Sheet Activity List CSI
C2: Activity list | D2: 1 | E2: 2 | F2: 3 | G2: 4 | H2: 5 | I2: 6 | J2: 7
C3: Old Activity Code | D3: Activity Code | E3: Activity description | F3: Div. | G3: Division Description | H3: Sub Division | I3: Extension | J3: Sub Division Description
A4: =COUNTIF($D$4:$D$146,D4) -> 1 | B4: Excavation Work for Sandy Soil | C4: 0201 | D4: =H4&"-"&I4 -> 02300-01 | E4: Excavation Work for Sandy Soil | F4: 02 | G4: EarthWork | H4: 02300 | I4: 01 | J4: Earthwork
A5: =COUNTIF($D$4:$D$146,D5) -> 1 | B5: Excavation Work for Clay | C5: 0202 | D5: =H5&"-"&I5 -> 02300-02 | E5: Excavation Work for Clay | F5: 02 | G5: EarthWork | H5: 02300 | I5: 02 | J5: Earthwork
A6: =COUNTIF($D$4:$D$146,D6) -> 1 | B6: Excavation Work for Rocky Soil | C6: 0203 | D6: =H6&"-"&I6 -> 02300-03 | E6: Excavation Work for Rocky Soil | F6: 02 | G6: EarthWork | H6: 02300 | I6: 03 | J6: Earthwork
A7: =COUNTIF($D$4:$D$146,D7) -> 1 | B7: Excavation Work for Sandy Soil Including Disposal | C7: 0204 | D7: =H7&"-"&I7 -> 02300-04 | E7: Excavation Work for Sandy Soil Including Disposal | F7: 02 | G7: EarthWork | H7: 02300 | I7: 04 | J7: Earthwork
A8: =COUNTIF($D$4:$D$146,D8) -> 1 | B8: Excavation Work for Clay Including Disposal | C8: 0205 | D8: =H8&"-"&I8 -> 02300-05 | E8: Excavation Work for Clay Including Disposal | F8: 02 | G8: EarthWork | H8: 02300 | I8: 05 | J8: Earthwork
A9: =COUNTIF($D$4:$D$146,D9) -> 1 | B9: Excavation Work for Rocky Soil Including Disposal | C9: 0206 | D9: =H9&"-"&I9 -> 02300-06 | E9: Excavation Work for Rocky Soil Including Disposal | F9: 02 | G9: EarthWork | H9: 02300 | I9: 06 | J9: Earthwork
A10: =COUNTIF($D$4:$D$146,D10) -> 1 | B10: Dewatering Work | C10: 0207 | D10: =H10&"-"&I10 -> 02100-01 | E10: Dewatering Work | F10: 02 | G10: EarthWork | H10: 02100 | I10: 01 | J10: Site Remediation
A11: =COUNTIF($D$4:$D$146,D11) -> 1 | B11: Shoring System | C11: 0208 | D11: =H11&"-"&I11 -> 02300-07 | E11: Shoring System | F11: 02 | G11: EarthWork | H11: 02300 | I11: 07 | J11: Earthwork
A12: =COUNTIF($D$4:$D$146,D12) -> 1 | B12: Backfilling Work For Open Area with Excavated Material Including Compaction | C12: 0209 | D12: =H12&"-"&I12 -> 02300-08 | E12: Backfilling Work For Open Area with Excavated Material Including Compaction | F12: 02 | G12: EarthWork | H12: 02300 | I12: 08 | J12: Earthwork
A13: =COUNTIF($D$4:$D$146,D13) -> 1 | B13: Backfilling Work For Open Area with Imported Material Including Compaction | C13: 0210 | D13: =H13&"-"&I13 -> 02300-09 | E13: Backfilling Work For Open Area with Imported Material Including Compaction | F13: 02 | G13: EarthWork | H13: 02300 | I13: 09 | J13: Earthwork
A14: =COUNTIF($D$4:$D$146,D14) -> 1 | B14: Backfilling Work For Trenches with Excavated Material Including Compaction | C14: 0211 | D14: =H14&"-"&I14 -> 02300-10 | E14: Backfilling Work For Trenches with Excavated Material Including Compaction | F14: 02 | G14: EarthWork | H14: 02300 | I14: 10 | J14: Earthwork
A15: =COUNTIF($D$4:$D$146,D15) -> 1 | B15: Backfilling Work For Trenches with Imported Material Including Compaction | C15: 0212 | D15: =H15&"-"&I15 -> 02300-11 | E15: Backfilling Work For Trenches with Imported Material Including Compaction | F15: 02 | G15: EarthWork | H15: 02300 | I15: 11 | J15: Earthwork
... A35: =COUNTIF($D$4:$D$146,D35) -> 1 | B35: Marking Work | C35: 0232 | D35: =H35&"-"&I35 -> 09900-04 | E35: Marking Work | F35: 02 | G35: EarthWork | H35: 09900 | I35: 04 | J35: Paints & Coatings
A36: =COUNTIF($D$4:$D$146,D36) -> 1 | B36: Installing Newgersy Barriers | C36: 0233 | D36: =H36&"-"&I36 -> 02700-10 | E36: Installing Newgersy Barriers | F36: 02 | G36: EarthWork | H36: 02700 | I36: 10 | J36: Bases, Ballast,Pavement & Appurtenances
A37: =COUNTIF($D$4:$D$146,D37) -> 1 | B37: Installing Sign Boards | C37: 0234 | D37: =H37&"-"&I37 -> 10100-02 | E37: Installing Sign Boards | F37: 02 | G37: EarthWork | H37: 10100 | I37: 02 | J37: Visual Display Boards
A38: =COUNTIF($D$4:$D$146,D38) -> 1 | B38: Installing Road Rails | C38: 0235 | D38: =H38&"-"&I38 -> 05650-01 | E38: Installing Road Rails | F38: 02 | G38: EarthWork | H38: 05650 | I38: 01 | J38: Railroad Track & Accessories
A39: =COUNTIF($D$4:$D$146,D39) -> 1 | B39: Removing Obstacles | C39: 0237 | D39: =H39&"-"&I39 -> 02200-01 | E39: Removing Obstacles | F39: 02 | G39: EarthWork | H39: 02200 | I39: 01 | J39: Site Prepartion
A40: =COUNTIF($D$4:$D$146,D40) -> 1 | B40: Clearing and Grubbing | C40: 0238 | D40: =H40&"-"&I40 -> 02200-02 | E40: Clearing and Grubbing | F40: 02 | G40: EarthWork | H40: 02200 | I40: 02 | J40: Site Prepartion
A41: =COUNTIF($D$4:$D$146,D41) -> 1 | B41: Diversion of Telephone Cables | C41: 0239 | D41: =H41&"-"&I41 -> 02500-01 | E41: Diversion of Telephone Cables | F41: 02 | G41: EarthWork | H41: 02500 | I41: 01 | J41: Utility Services
A42: =COUNTIF($D$4:$D$146,D42) -> 1 | B42: Diversion of Low Voltage Cables | C42: 0240 | D42: =H42&"-"&I42 -> 02500-02 | E42: Diversion of Low Voltage Cables | F42: 02 | G42: EarthWork | H42: 02500 | I42: 02 | J42: Utility Services
A43: =COUNTIF($D$4:$D$146,D43) -> 1 | B43: Diversion of High Voltage Cables | C43: 0241 | D43: =H43&"-"&I43 -> 02500-03 | E43: Diversion of High Voltage Cables | F43: 02 | G43: EarthWork | H43: 02500 | I43: 03 | J43: Utility Services
A44: =COUNTIF($D$4:$D$146,D44) -> 1 | B44: Diversion of Traffic | C44: 0242 | D44: =H44&"-"&I44 -> 02500-04 | E44: Diversion of Traffic | F44: 02 | G44: EarthWork | H44: 02500 | I44: 04 | J44: Utility Services
A45: =COUNTIF($D$4:$D$146,D45) -> 1 | B45: Diversion of Flood Water | C45: 0243 | D45: =H45&"-"&I45 -> 02500-05 | E45: Diversion of Flood Water | F45: 02 | G45: EarthWork | H45: 02500 | I45: 05 | J45: Utility Services
A46: =COUNTIF($D$4:$D$146,D46) -> 1 | B46: Diversion of Drinking Water | C46: 0244 | D46: =H46&"-"&I46 -> 02500-06 | E46: Diversion of Drinking Water | F46: 02 | G46: EarthWork | H46: 02500 | I46: 06 | J46: Utility Services
A47: =COUNTIF($D$4:$D$146,D47) -> 1 | B47: Removal of Concrete Building Including Blocks | C47: 0245 | D47: =H47&"-"&I47 -> 02200-03 | E47: Removal of Concrete Building Including Blocks | F47: 02 | G47: EarthWork | H47: 02200 | I47: 03 | J47: Site Prepartion
A48: =COUNTIF($D$4:$D$146,D48) -> 1 | B48: Removal of Septic Tanks | C48: 0247 | D48: =H48&"-"&I48 -> 02200-04 | E48: Removal of Septic Tanks | F48: 02 | G48: EarthWork | H48: 02200 | I48: 04 | J48: Site Prepartion
... A146: =COUNTIF($D$4:$D$146,D146) -> 1 | B146: Electrical Work | C146: 1601 | D146: =H146&"-"&I146 -> 16050-01 | E146: Electrical Work | F146: 16 | G146: ElectricalWork | H146: 16050 | I146: 01 | J146: Basic Electrical Materials and Methods

Sheet Resource Unique List 
G2: Unique List For Resources
C3: Resource Code | D3: Resource Category | E3: Resource Description | F3: UOM | G3: Resource Main Code | H3: Ext | I3: Ext Description | J3: Rate
C4: =G4&"-"&H4 -> 02100105-001 | D4: 1 | E4: Antitermite Material | F4: Litre | G4: 02100105 | H4: 001
C5: =G5&"-"&H5 -> 02300105-001 | D5: 1 | E5: Backfillig Material | F5: M3 | G5: 02300105 | H5: 001
C6: =G6&"-"&H6 -> 02700105-001 | D6: 1 | E6: Asphalt | F6: M3 | G6: 02700105 | H6: 001
C7: =G7&"-"&H7 -> 02700110-001 | D7: 1 | E7: Sub-Grade Material | F7: M3 | G7: 02700110 | H7: 001
C8: =G8&"-"&H8 -> 02700115-001 | D8: 1 | E8: Sub-Base Material | F8: M3 | G8: 02700115 | H8: 001
C9: =G9&"-"&H9 -> 02700120-001 | D9: 1 | E9: Base Material | F9: M3 | G9: 02700120 | H9: 001
C10: =G10&"-"&H10 -> 02700125-001 | D10: 1 | E10: New gersy material | F10: L.M | G10: 02700125 | H10: 001
C11: =G11&"-"&H11 -> 02700130-001 | D11: 1 | E11: MC Material | F11: Litre | G11: 02700130 | H11: 001
C12: =G12&"-"&H12 -> 02700135-001 | D12: 1 | E12: RC Material | F12: Litre | G12: 02700135 | H12: 001
C13: =G13&"-"&H13 -> 02700140-001 | D13: 1 | E13: Concrete Tiles | F13: M2 | G13: 02700140 | H13: 001
C14: =G14&"-"&H14 -> 02700145-001 | D14: 1 | E14: Interlock Tiles | F14: M2 | G14: 02700145 | H14: 001
C15: =G15&"-"&H15 -> 03300105-001 | D15: 1 | E15: Concrete Chemicals | F15: Litre | G15: 03300105 | H15: 001
... C132: =G132&"-"&H132 -> 09600220-001 | D132: 2 | E132: Epoxy Painting Sub-Contractor | F132: LS | G132: 09600220 | H132: 001
C133: =G133&"-"&H133 -> 03300305-001 | D133: 3 | E133: Carpentary Crew | F133: MH | G133: 03300305 | H133: 001 | J133: 10.123602
C134: =G134&"-"&H134 -> 15200315-001 | D134: 3 | E134: Ex. Plumping (Manhole) | F134: MH | G134: 15200315 | H134: 001 | J134: 9.4675938
C135: =G135&"-"&H135 -> 02700310-001 | D135: 3 | E135: Asphalt Workers Crew | F135: MH | G135: 02700310 | H135: 001 | J135: 14.265691
C136: =G136&"-"&H136 -> 02300315-001 | D136: 3 | E136: Ex. Plumping (Pipes) | F136: MH | G136: 02300315 | H136: 001 | J136: 10.573304
C137: =G137&"-"&H137 -> 02300320-001 | D137: 3 | E137: General Workers Crew | F137: MH | G137: 02300320 | H137: 001 | J137: 8.3745532
C138: =G138&"-"&H138 -> 04200305-001 | D138: 3 | E138: Block Work Crew | F138: MH | G138: 04200305 | H138: 001 | J138: 8.4582914
C139: =G139&"-"&H139 -> 02100305-001 | D139: 3 | E139: Dewatering Crew | F139: MH | G139: 02100305 | H139: 001 | J139: 11.020056
C140: =G140&"-"&H140 -> 09200305-001 | D140: 3 | E140: Plastering Work Crew | F140: MH | G140: 09200305 | H140: 001 | J140: 8.9983698
C141: =G141&"-"&H141 -> 15200310-001 | D141: 3 | E141: Sewage (Manhole) | F141: MH | G141: 15200310 | H141: 001 | J141: 8.7146181
C142: =G142&"-"&H142 -> 09300305-001 | D142: 3 | E142: Tile Fixing Crew | F142: MH | G142: 09300305 | H142: 001 | J142: 9.2877564
C143: =G143&"-"&H143 -> 03400305-001 | D143: 3 | E143: Precast Concrete Crew | F143: MH | G143: 03400305 | H143: 001 | J143: 10.389741
C144: =G144&"-"&H144 -> 02700305-001 | D144: 3 | E144: Surveying Crew | F144: MH | G144: 02700305 | H144: 001 | J144: 21.151771
... C151: =G151&"-"&H151 -> 09900305-001 | D151: 3 | E151: Painting Crew | F151: MH | G151: 09900305 | H151: 001 | J151: 9.649638
C152: =G152&"-"&H152 -> 02700425-001 | D152: 4 | E152: Ashphalt Finisher | F152: EH | G152: 02700425 | H152: 001 | I152: Normal | J152: 30.851047
C153: =G153&"-"&H153 -> 02700425-002 | D153: 4 | E153: Ashphalt Finisher | F153: EH | G153: 02700425 | H153: 002 | I153: Big | J153: 70.132348
C154: =G154&"-"&H154 -> 02700410-001 | D154: 4 | E154: Asphalt Compactor | F154: EH | G154: 02700410 | H154: 001 | I154: Single Drum | J154: 17.841963
C155: =G155&"-"&H155 -> 02700410-002 | D155: 4 | E155: Asphalt Compactor | F155: EH | G155: 02700410 | H155: 002 | I155: Double Dum | J155: 36.107463
C156: =G156&"-"&H156 -> 02700440-001 | D156: 4 | E156: Asphalt Cutter | F156: EH | G156: 02700440 | H156: 001 | I156: Normal | J156: 11.643363
C157: =G157&"-"&H157 -> 02300450-001 | D157: 4 | E157: Bobcat | F157: EH | G157: 02300450 | H157: 001 | I157: Big | J157: 27.469935
C158: =G158&"-"&H158 -> 02300450-002 | D158: 4 | E158: Bobcat | F158: EH | G158: 02300450 | H158: 002 | I158: Small | J158: 16.169469
C159: =G159&"-"&H159 -> 03400405-001 | D159: 4 | E159: Crane | F159: EH | G159: 03400405 | H159: 001 | I159: Telescope | J159: 46.643058
C160: =G160&"-"&H160 -> 03400405-002 | D160: 4 | E160: Crane | F160: EH | G160: 03400405 | H160: 002 | I160: Tower | J160: 87.557706
C161: =G161&"-"&H161 -> 02100405-001 | D161: 4 | E161: De-Watering Pump | F161: EH | G161: 02100405 | H161: 001 | I161: Normal | J161: 14.548931
C162: =G162&"-"&H162 -> 02200405-001 | D162: 4 | E162: Dozer | F162: EH | G162: 02200405 | H162: 001 | I162: Crawler | J162: 126.52665
C163: =G163&"-"&H163 -> 02200405-002 | D163: 4 | E163: Dozer | F163: EH | G163: 02200405 | H163: 002 | I163: Wheel | J163: 52.864196
...

Sheet Mat. List CSI
G1: 3 | H1: 4 | J1: 7
D2: Code System For Materials
D3: Old Activity Code | E3: Activity Code | F3: Activity description | G3: Div | H3: Division Description | I3: Sub Division | J3: Sub Division Description | K3: Resource Description | L3: Resource Order | M3: Resource Main Code | N3: Resource Main Code Mod.
D4: 0210 | E4: =VLOOKUP(F4,'Activity List CSI'!$B$4:$D$146,3,0) -> 02300-09 | F4: Backfilling Work For Open Area with Imported Material Including Compaction | G4: =VLOOKUP($E4,'Activity List CSI'!$D$4:$J$146,'Mat. List CSI'!G$1,0) -> 02 | H4: =VLOOKUP($E4,'Activity List CSI'!$D$4:$J$146,'Mat. List CSI'!H$1,0) -> EarthWork | I4: =VLOOKUP(D4,'Activity List CSI'!$C$4:$H$146,6,0) -> 02300 | J4: =VLOOKUP($E4,'Activity List CSI'!$D$4:$J$146,'Mat. List CSI'!J$1,0) -> Earthwork | K4: Backfillig Material | L4: 105 | M4: =I4&L4 -> 02300105 | N4: =M4 -> 02300105
D5: 0210 | E5: =VLOOKUP(F5,'Activity List CSI'!$B$4:$D$146,3,0) -> 02300-09 | F5: Backfilling Work For Open Area with Imported Material Including Compaction | G5: =VLOOKUP($E5,'Activity List CSI'!$D$4:$J$146,'Mat. List CSI'!G$1,0) -> 02 | H5: =VLOOKUP($E5,'Activity List CSI'!$D$4:$J$146,'Mat. List CSI'!H$1,0) -> EarthWork | I5: =VLOOKUP(D5,'Activity List CSI'!$C$4:$H$146,6,0) -> 02300 | J5: =VLOOKUP($E5,'Activity List CSI'!$D$4:$J$146,'Mat. List CSI'!J$1,0) -> Earthwork | K5: Backfillig Material | L5: 105 | M5: =I5&L5 -> 02300105 | N5: =M5 -> 02300105
D6: 0212 | E6: =VLOOKUP(F6,'Activity List CSI'!$B$4:$D$146,3,0) -> 02300-11 | F6: Backfilling Work For Trenches with Imported Material Including Compaction | G6: =VLOOKUP($E6,'Activity List CSI'!$D$4:$J$146,'Mat. List CSI'!G$1,0) -> 02 | H6: =VLOOKUP($E6,'Activity List CSI'!$D$4:$J$146,'Mat. List CSI'!H$1,0) -> EarthWork | I6: =VLOOKUP(D6,'Activity List CSI'!$C$4:$H$146,6,0) -> 02300 | J6: =VLOOKUP($E6,'Activity List CSI'!$D$4:$J$146,'Mat. List CSI'!J$1,0) -> Earthwork | K6: Backfillig Material | L6: 105 | M6: =I6&L6 -> 02300105 | N6: =M6 -> 02300105
D7: 0212 | E7: =VLOOKUP(F7,'Activity List CSI'!$B$4:$D$146,3,0) -> 02300-11 | F7: Backfilling Work For Trenches with Imported Material Including Compaction | G7: =VLOOKUP($E7,'Activity List CSI'!$D$4:$J$146,'Mat. List CSI'!G$1,0) -> 02 | H7: =VLOOKUP($E7,'Activity List CSI'!$D$4:$J$146,'Mat. List CSI'!H$1,0) -> EarthWork | I7: =VLOOKUP(D7,'Activity List CSI'!$C$4:$H$146,6,0) -> 02300 | J7: =VLOOKUP($E7,'Activity List CSI'!$D$4:$J$146,'Mat. List CSI'!J$1,0) -> Earthwork | K7: Backfillig Material | L7: 105 | M7: =I7&L7 -> 02300105 | N7: =M7 -> 02300105
D8: 0214 | E8: =VLOOKUP(F8,'Activity List CSI'!$B$4:$D$146,3,0) -> 02300-13 | F8: Backfilling Work between Footings with Imported Material Including Compaction | G8: =VLOOKUP($E8,'Activity List CSI'!$D$4:$J$146,'Mat. List CSI'!G$1,0) -> 02 | H8: =VLOOKUP($E8,'Activity List CSI'!$D$4:$J$146,'Mat. List CSI'!H$1,0) -> EarthWork | I8: =VLOOKUP(D8,'Activity List CSI'!$C$4:$H$146,6,0) -> 02300 | J8: =VLOOKUP($E8,'Activity List CSI'!$D$4:$J$146,'Mat. List CSI'!J$1,0) -> Earthwork | K8: Backfillig Material | L8: 105 | M8: =I8&L8 -> 02300105 | N8: =M8 -> 02300105
D9: 0214 | E9: =VLOOKUP(F9,'Activity List CSI'!$B$4:$D$146,3,0) -> 02300-13 | F9: Backfilling Work between Footings with Imported Material Including Compaction | G9: =VLOOKUP($E9,'Activity List CSI'!$D$4:$J$146,'Mat. List CSI'!G$1,0) -> 02 | H9: =VLOOKUP($E9,'Activity List CSI'!$D$4:$J$146,'Mat. List CSI'!H$1,0) -> EarthWork | I9: =VLOOKUP(D9,'Activity List CSI'!$C$4:$H$146,6,0) -> 02300 | J9: =VLOOKUP($E9,'Activity List CSI'!$D$4:$J$146,'Mat. List CSI'!J$1,0) -> Earthwork | K9: Backfillig Material | L9: 105 | M9: =I9&L9 -> 02300105 | N9: =M9 -> 02300105
D10: 0215 | E10: =VLOOKUP(F10,'Activity List CSI'!$B$4:$D$146,3,0) -> 02300-14 | F10: Soil Replacement Work including Compaction | G10: =VLOOKUP($E10,'Activity List CSI'!$D$4:$J$146,'Mat. List CSI'!G$1,0) -> 02 | H10: =VLOOKUP($E10,'Activity List CSI'!$D$4:$J$146,'Mat. List CSI'!H$1,0) -> EarthWork | I10: =VLOOKUP(D10,'Activity List CSI'!$C$4:$H$146,6,0) -> 02300 | J10: =VLOOKUP($E10,'Activity List CSI'!$D$4:$J$146,'Mat. List CSI'!J$1,0) -> Earthwork | K10: Backfillig Material | L10: 105 | M10: =I10&L10 -> 02300105 | N10: =M10 -> 02300105
D11: 0215 | E11: =VLOOKUP(F11,'Activity List CSI'!$B$4:$D$146,3,0) -> 02300-14 | F11: Soil Replacement Work including Compaction | G11: =VLOOKUP($E11,'Activity List CSI'!$D$4:$J$146,'Mat. List CSI'!G$1,0) -> 02 | H11: =VLOOKUP($E11,'Activity List CSI'!$D$4:$J$146,'Mat. List CSI'!H$1,0) -> EarthWork | I11: =VLOOKUP(D11,'Activity List CSI'!$C$4:$H$146,6,0) -> 02300 | J11: =VLOOKUP($E11,'Activity List CSI'!$D$4:$J$146,'Mat. List CSI'!J$1,0) -> Earthwork | K11: Backfillig Material | L11: 105 | M11: =I11&L11 -> 02300105 | N11: =M11 -> 02300105
D12: 0221 | E12: =VLOOKUP(F12,'Activity List CSI'!$B$4:$D$146,3,0) -> 02300-20 | F12: Drainage Layer Under Slab On Grade Work | G12: =VLOOKUP($E12,'Activity List CSI'!$D$4:$J$146,'Mat. List CSI'!G$1,0) -> 02 | H12: =VLOOKUP($E12,'Activity List CSI'!$D$4:$J$146,'Mat. List CSI'!H$1,0) -> EarthWork | I12: =VLOOKUP(D12,'Activity List CSI'!$C$4:$H$146,6,0) -> 02300 | J12: =VLOOKUP($E12,'Activity List CSI'!$D$4:$J$146,'Mat. List CSI'!J$1,0) -> Earthwork | K12: UPVC Pipes | L12: 130 | M12: =I12&L12 -> 02300130 | N12: 15100130
D13: 0221 | E13: =VLOOKUP(F13,'Activity List CSI'!$B$4:$D$146,3,0) -> 02300-20 | F13: Drainage Layer Under Slab On Grade Work | G13: =VLOOKUP($E13,'Activity List CSI'!$D$4:$J$146,'Mat. List CSI'!G$1,0) -> 02 | H13: =VLOOKUP($E13,'Activity List CSI'!$D$4:$J$146,'Mat. List CSI'!H$1,0) -> EarthWork | I13: =VLOOKUP(D13,'Activity List CSI'!$C$4:$H$146,6,0) -> 02300 | J13: =VLOOKUP($E13,'Activity List CSI'!$D$4:$J$146,'Mat. List CSI'!J$1,0) -> Earthwork | K13: UPVC Pipes | L13: 130 | M13: =I13&L13 -> 02300130 | N13: 15100130
D14: 0222 | E14: =VLOOKUP(F14,'Activity List CSI'!$B$4:$D$146,3,0) -> 02100-02 | F14: Application Of Soil Treatment For Termite Control | G14: =VLOOKUP($E14,'Activity List CSI'!$D$4:$J$146,'Mat. List CSI'!G$1,0) -> 02 | H14: =VLOOKUP($E14,'Activity List CSI'!$D$4:$J$146,'Mat. List CSI'!H$1,0) -> EarthWork | I14: =VLOOKUP(D14,'Activity List CSI'!$C$4:$H$146,6,0) -> 02100 | J14: =VLOOKUP($E14,'Activity List CSI'!$D$4:$J$146,'Mat. List CSI'!J$1,0) -> Site Remediation | K14: Antitermite Material | L14: 105 | M14: =I14&L14 -> 02100105 | N14: =M14 -> 02100105
D15: 0225 | E15: =VLOOKUP(F15,'Activity List CSI'!$B$4:$D$146,3,0) -> 02700-03 | F15: Subgrade Work | G15: =VLOOKUP($E15,'Activity List CSI'!$D$4:$J$146,'Mat. List CSI'!G$1,0) -> 02 | H15: =VLOOKUP($E15,'Activity List CSI'!$D$4:$J$146,'Mat. List CSI'!H$1,0) -> EarthWork | I15: =VLOOKUP(D15,'Activity List CSI'!$C$4:$H$146,6,0) -> 02700 | J15: =VLOOKUP($E15,'Activity List CSI'!$D$4:$J$146,'Mat. List CSI'!J$1,0) -> Bases, Ballast,Pavement & Appurtenances | K15: Sub-Grade Material | L15: 110 | M15: =I15&L15 -> 02700110 | N15: =M15 -> 02700110
D16: 0225 | E16: =VLOOKUP(F16,'Activity List CSI'!$B$4:$D$146,3,0) -> 02700-03 | F16: Subgrade Work | G16: =VLOOKUP($E16,'Activity List CSI'!$D$4:$J$146,'Mat. List CSI'!G$1,0) -> 02 | H16: =VLOOKUP($E16,'Activity List CSI'!$D$4:$J$146,'Mat. List CSI'!H$1,0) -> EarthWork | I16: =VLOOKUP(D16,'Activity List CSI'!$C$4:$H$146,6,0) -> 02700 | J16: =VLOOKUP($E16,'Activity List CSI'!$D$4:$J$146,'Mat. List CSI'!J$1,0) -> Bases, Ballast,Pavement & Appurtenances | K16: Sub-Grade Material | L16: 110 | M16: =I16&L16 -> 02700110 | N16: =M16 -> 02700110
D17: 0226 | E17: =VLOOKUP(F17,'Activity List CSI'!$B$4:$D$146,3,0) -> 02700-04 | F17: Subbase Work | G17: =VLOOKUP($E17,'Activity List CSI'!$D$4:$J$146,'Mat. List CSI'!G$1,0) -> 02 | H17: =VLOOKUP($E17,'Activity List CSI'!$D$4:$J$146,'Mat. List CSI'!H$1,0) -> EarthWork | I17: =VLOOKUP(D17,'Activity List CSI'!$C$4:$H$146,6,0) -> 02700 | J17: =VLOOKUP($E17,'Activity List CSI'!$D$4:$J$146,'Mat. List CSI'!J$1,0) -> Bases, Ballast,Pavement & Appurtenances | K17: Sub-Base Material | L17: 115 | M17: =I17&L17 -> 02700115 | N17: =M17 -> 02700115
D18: 0226 | E18: =VLOOKUP(F18,'Activity List CSI'!$B$4:$D$146,3,0) -> 02700-04 | F18: Subbase Work | G18: =VLOOKUP($E18,'Activity List CSI'!$D$4:$J$146,'Mat. List CSI'!G$1,0) -> 02 | H18: =VLOOKUP($E18,'Activity List CSI'!$D$4:$J$146,'Mat. List CSI'!H$1,0) -> EarthWork | I18: =VLOOKUP(D18,'Activity List CSI'!$C$4:$H$146,6,0) -> 02700 | J18: =VLOOKUP($E18,'Activity List CSI'!$D$4:$J$146,'Mat. List CSI'!J$1,0) -> Bases, Ballast,Pavement & Appurtenances | K18: Sub-Base Material | L18: 115 | M18: =I18&L18 -> 02700115 | N18: =M18 -> 02700115
D19: 0227 | E19: =VLOOKUP(F19,'Activity List CSI'!$B$4:$D$146,3,0) -> 02700-05 | F19: Road Base Work (WBM) | G19: =VLOOKUP($E19,'Activity List CSI'!$D$4:$J$146,'Mat. List CSI'!G$1,0) -> 02 | H19: =VLOOKUP($E19,'Activity List CSI'!$D$4:$J$146,'Mat. List CSI'!H$1,0) -> EarthWork | I19: =VLOOKUP(D19,'Activity List CSI'!$C$4:$H$146,6,0) -> 02700 | J19: =VLOOKUP($E19,'Activity List CSI'!$D$4:$J$146,'Mat. List CSI'!J$1,0) -> Bases, Ballast,Pavement & Appurtenances | K19: Base Material | L19: 120 | M19: =I19&L19 -> 02700120 | N19: =M19 -> 02700120
D20: 0227 | E20: =VLOOKUP(F20,'Activity List CSI'!$B$4:$D$146,3,0) -> 02700-05 | F20: Road Base Work (WBM) | G20: =VLOOKUP($E20,'Activity List CSI'!$D$4:$J$146,'Mat. List CSI'!G$1,0) -> 02 | H20: =VLOOKUP($E20,'Activity List CSI'!$D$4:$J$146,'Mat. List CSI'!H$1,0) -> EarthWork | I20: =VLOOKUP(D20,'Activity List CSI'!$C$4:$H$146,6,0) -> 02700 | J20: =VLOOKUP($E20,'Activity List CSI'!$D$4:$J$146,'Mat. List CSI'!J$1,0) -> Bases, Ballast,Pavement & Appurtenances | K20: Base Material | L20: 120 | M20: =I20&L20 -> 02700120 | N20: =M20 -> 02700120
D21: 0228 | E21: =VLOOKUP(F21,'Activity List CSI'!$B$4:$D$146,3,0) -> 02700-06 | F21: Prime Coat (MC1) Work | G21: =VLOOKUP($E21,'Activity List CSI'!$D$4:$J$146,'Mat. List CSI'!G$1,0) -> 02 | H21: =VLOOKUP($E21,'Activity List CSI'!$D$4:$J$146,'Mat. List CSI'!H$1,0) -> EarthWork | I21: =VLOOKUP(D21,'Activity List CSI'!$C$4:$H$146,6,0) -> 02700 | J21: =VLOOKUP($E21,'Activity List CSI'!$D$4:$J$146,'Mat. List CSI'!J$1,0) -> Bases, Ballast,Pavement & Appurtenances | K21: MC Material | L21: 130 | M21: =I21&L21 -> 02700130 | N21: =M21 -> 02700130
D22: 0228 | E22: =VLOOKUP(F22,'Activity List CSI'!$B$4:$D$146,3,0) -> 02700-06 | F22: Prime Coat (MC1) Work | G22: =VLOOKUP($E22,'Activity List CSI'!$D$4:$J$146,'Mat. List CSI'!G$1,0) -> 02 | H22: =VLOOKUP($E22,'Activity List CSI'!$D$4:$J$146,'Mat. List CSI'!H$1,0) -> EarthWork | I22: =VLOOKUP(D22,'Activity List CSI'!$C$4:$H$146,6,0) -> 02700 | J22: =VLOOKUP($E22,'Activity List CSI'!$D$4:$J$146,'Mat. List CSI'!J$1,0) -> Bases, Ballast,Pavement & Appurtenances | K22: MC Material | L22: 130 | M22: =I22&L22 -> 02700130 | N22: =M22 -> 02700130
D23: 0229 | E23: =VLOOKUP(F23,'Activity List CSI'!$B$4:$D$146,3,0) -> 02700-07 | F23: Base Coarse Work | G23: =VLOOKUP($E23,'Activity List CSI'!$D$4:$J$146,'Mat. List CSI'!G$1,0) -> 02 | H23: =VLOOKUP($E23,'Activity List CSI'!$D$4:$J$146,'Mat. List CSI'!H$1,0) -> EarthWork | I23: =VLOOKUP(D23,'Activity List CSI'!$C$4:$H$146,6,0) -> 02700 | J23: =VLOOKUP($E23,'Activity List CSI'!$D$4:$J$146,'Mat. List CSI'!J$1,0) -> Bases, Ballast,Pavement & Appurtenances | K23: Asphalt | L23: 105 | M23: =I23&L23 -> 02700105 | N23: =M23 -> 02700105
D24: 0229 | E24: =VLOOKUP(F24,'Activity List CSI'!$B$4:$D$146,3,0) -> 02700-07 | F24: Base Coarse Work | G24: =VLOOKUP($E24,'Activity List CSI'!$D$4:$J$146,'Mat. List CSI'!G$1,0) -> 02 | H24: =VLOOKUP($E24,'Activity List CSI'!$D$4:$J$146,'Mat. List CSI'!H$1,0) -> EarthWork | I24: =VLOOKUP(D24,'Activity List CSI'!$C$4:$H$146,6,0) -> 02700 | J24: =VLOOKUP($E24,'Activity List CSI'!$D$4:$J$146,'Mat. List CSI'!J$1,0) -> Bases, Ballast,Pavement & Appurtenances | K24: Asphalt | L24: 105 | M24: =I24&L24 -> 02700105 | N24: =M24 -> 02700105
D25: 0230 | E25: =VLOOKUP(F25,'Activity List CSI'!$B$4:$D$146,3,0) -> 02700-08 | F25: Tack Coat (RC )Work | G25: =VLOOKUP($E25,'Activity List CSI'!$D$4:$J$146,'Mat. List CSI'!G$1,0) -> 02 | H25: =VLOOKUP($E25,'Activity List CSI'!$D$4:$J$146,'Mat. List CSI'!H$1,0) -> EarthWork | I25: =VLOOKUP(D25,'Activity List CSI'!$C$4:$H$146,6,0) -> 02700 | J25: =VLOOKUP($E25,'Activity List CSI'!$D$4:$J$146,'Mat. List CSI'!J$1,0) -> Bases, Ballast,Pavement & Appurtenances | K25: RC Material | L25: 135 | M25: =I25&L25 -> 02700135 | N25: =M25 -> 02700135
... D143: 0401 | E143: =VLOOKUP(F143,'Activity List CSI'!$B$4:$D$146,3,0) -> 04200-01 | F143: Block Work | G143: =VLOOKUP($E143,'Activity List CSI'!$D$4:$J$146,'Mat. List CSI'!G$1,0) -> 04 | H143: =VLOOKUP($E143,'Activity List CSI'!$D$4:$J$146,'Mat. List CSI'!H$1,0) -> BlockWork | I143: =VLOOKUP(D143,'Activity List CSI'!$C$4:$H$146,6,0) -> 04200 | J143: =VLOOKUP($E143,'Activity List CSI'!$D$4:$J$146,'Mat. List CSI'!J$1,0) -> Masonary Units | K143: Block Accessories | L143: 125 | M143: =I143&L143 -> 04200125 | N143: =M143 -> 04200125
D144: 0401 | E144: =VLOOKUP(F144,'Activity List CSI'!$B$4:$D$146,3,0) -> 04200-01 | F144: Block Work | G144: =VLOOKUP($E144,'Activity List CSI'!$D$4:$J$146,'Mat. List CSI'!G$1,0) -> 04 | H144: =VLOOKUP($E144,'Activity List CSI'!$D$4:$J$146,'Mat. List CSI'!H$1,0) -> BlockWork | I144: =VLOOKUP(D144,'Activity List CSI'!$C$4:$H$146,6,0) -> 04200 | J144: =VLOOKUP($E144,'Activity List CSI'!$D$4:$J$146,'Mat. List CSI'!J$1,0) -> Masonary Units | K144: Cement | L144: 105 | M144: =I144&L144 -> 04200105 | N144: 09200105
D145: 0401 | E145: =VLOOKUP(F145,'Activity List CSI'!$B$4:$D$146,3,0) -> 04200-01 | F145: Block Work | G145: =VLOOKUP($E145,'Activity List CSI'!$D$4:$J$146,'Mat. List CSI'!G$1,0) -> 04 | H145: =VLOOKUP($E145,'Activity List CSI'!$D$4:$J$146,'Mat. List CSI'!H$1,0) -> BlockWork | I145: =VLOOKUP(D145,'Activity List CSI'!$C$4:$H$146,6,0) -> 04200 | J145: =VLOOKUP($E145,'Activity List CSI'!$D$4:$J$146,'Mat. List CSI'!J$1,0) -> Masonary Units | K145: Sand | L145: 110 | M145: =I145&L145 -> 04200110 | N145: =M145 -> 04200110
D146: 0401 | E146: =VLOOKUP(F146,'Activity List CSI'!$B$4:$D$146,3,0) -> 04200-01 | F146: Block Work | G146: =VLOOKUP($E146,'Activity List CSI'!$D$4:$J$146,'Mat. List CSI'!G$1,0) -> 04 | H146: =VLOOKUP($E146,'Activity List CSI'!$D$4:$J$146,'Mat. List CSI'!H$1,0) -> BlockWork | I146: =VLOOKUP(D146,'Activity List CSI'!$C$4:$H$146,6,0) -> 04200 | J146: =VLOOKUP($E146,'Activity List CSI'!$D$4:$J$146,'Mat. List CSI'!J$1,0) -> Masonary Units | K146: Solid Blocks | L146: 115 | M146: =I146&L146 -> 04200115 | N146: =M146 -> 04200115
D147: 0401 | E147: =VLOOKUP(F147,'Activity List CSI'!$B$4:$D$146,3,0) -> 04200-01 | F147: Block Work | G147: =VLOOKUP($E147,'Activity List CSI'!$D$4:$J$146,'Mat. List CSI'!G$1,0) -> 04 | H147: =VLOOKUP($E147,'Activity List CSI'!$D$4:$J$146,'Mat. List CSI'!H$1,0) -> BlockWork | I147: =VLOOKUP(D147,'Activity List CSI'!$C$4:$H$146,6,0) -> 04200 | J147: =VLOOKUP($E147,'Activity List CSI'!$D$4:$J$146,'Mat. List CSI'!J$1,0) -> Masonary Units | K147: Block Accessories | L147: 125 | M147: =I147&L147 -> 04200125 | N147: =M147 -> 04200125
D148: 0401 | E148: =VLOOKUP(F148,'Activity List CSI'!$B$4:$D$146,3,0) -> 04200-01 | F148: Block Work | G148: =VLOOKUP($E148,'Activity List CSI'!$D$4:$J$146,'Mat. List CSI'!G$1,0) -> 04 | H148: =VLOOKUP($E148,'Activity List CSI'!$D$4:$J$146,'Mat. List CSI'!H$1,0) -> BlockWork | I148: =VLOOKUP(D148,'Activity List CSI'!$C$4:$H$146,6,0) -> 04200 | J148: =VLOOKUP($E148,'Activity List CSI'!$D$4:$J$146,'Mat. List CSI'!J$1,0) -> Masonary Units | K148: Cement | L148: 105 | M148: =I148&L148 -> 04200105 | N148: 09200105
