Workbook

Sheet Instructions
A1: DYNAMIC TENDER BID CALCULATION & PRICING WORKBOOK
A2: Contracting Company | Bridges • Tunnels • Buildings • Roads — Prepared 15 September 2026
A4: PURPOSE
A5: This workbook is a dynamic tender pricing model for a general contracting company active in Buildings, Roads, Bridges and Tunnels in Egypt. It links a fixed reference material-price list (averaged from Egyptian market data over the last 3 months) into project-specific Bills of Quantities, and rolls direct costs up through overheads, risk contingency, escalation, profit, bonds/insurance and VAT into a final bid price, using contractor-configurable thresholds.
A9: HOW TO USE
A10: 1. Review / update 'Fixed Material Prices' with your own supplier quotations if more current data is available.
A11: 2. Review 'Concrete Mix Calculator' — concrete cost per grade recalculates automatically from cement/sand/gravel prices.
A12: 3. Check 'Labor & Equipment Rates' and adjust to your actual crew wages / owned or rented plant rates.
A13: 4. Set your commercial thresholds in 'Thresholds & Assumptions' (overheads, contingency, margin, escalation, bonds, VAT...).
A14: 5. Go to the relevant BOQ tab(s) (Buildings / Roads / Bridges / Tunnels) and enter quantities; pick a Material Code from
A15: the dropdown where relevant — the unit price fills in automatically. Enter labor/equipment/subcontract rates per unit.
A16: 6. Open 'Bid Summary Dashboard' — mark which scope(s) are included in this bid, set risk level and profit margin per
... A19: COLOR LEGEND
A20: Blue text | B20: Editable input — type your own value here
A21: Black text | B21: Formula — do not overwrite, it calculates automatically
A22: Green text | B22: Live link pulling a value from another sheet
A23: Yellow fill | B23: Key commercial assumption / threshold — review before every bid
A24: Light-blue fill | B24: Recommended cell to fill in for this template
A26: IMPORTANT DISCLAIMER ON MATERIAL PRICES
A27: Fixed material prices in this workbook are representative averages compiled from Egyptian market/factory price surveys and official producer price lists published between June and September 2026 (see Source column on the 'Fixed Material Prices' sheet for each item). Egyptian construction material prices (especially steel and cement) can move weekly. These figures are a sound planning baseline but MUST be re-verified against current supplier/factory quotations before a bid is finally submitted. Items marked 'Estimate – Verify' in the Confidence column were not confirmed against a primary factory price list and require a direct supplier quotation.
A32: WORKBOOK MAP
A33: Instructions | B33: This sheet
A34: Fixed Material Prices | B34: Reference price list — 3-month average Egyptian market prices (EGP)
A35: Concrete Mix Calculator | B35: Computes cost/m3 for concrete grades C15–C50 from cement/sand/gravel prices
A36: Labor & Equipment Rates | B36: Reference daily wage & plant rental rates
A37: Thresholds & Assumptions | B37: All commercial thresholds: overheads, contingency, margin, escalation, bonds, insurance, tax, wastage, financing
A38: BOQ - Buildings | B38: Bill of quantities & pricing build-up for building works
A39: BOQ - Roads | B39: Bill of quantities & pricing build-up for road works
A40: BOQ - Bridges | B40: Bill of quantities & pricing build-up for bridge works
A41: BOQ - Tunnels | B41: Bill of quantities & pricing build-up for tunnel works
A42: Bid Summary Dashboard | B42: Consolidated bid build-up, per-scope and combined, with threshold checks
A44: SOURCES (material & fuel prices, Jun–Sep 2026)
A45: • Egyptian Cement Co. official ex-works/consumer price list — egyptian-cement.com/products/products-prices
A46: • Cairo Mubasher, daily steel & cement market price roundups (Sep 2026) — cairomubasher.com
A47: • Masr24, daily steel rebar price roundups by mill (Sep 2026) — masr24.news
A48: • MatBuild, Egypt building materials price bulletins (brick, sand, gravel, cement, steel — Sep 2026) — matbuild.net
A49: • The Price 1 / Al-Malnews, sand, gravel & brick market prices (2026) — theprice1.com, almalnews.com
A50: • Aqaar24, daily construction labor wage survey (2026) — aqaar24.com
A51: • Ministry of Petroleum official fuel price notices (2026) — shofnews.com, elzmannews.com
A52: • Central Bank of Egypt Monetary Policy Report Q1 2026 & EnterpriseAM inflation coverage (Aug 2026) — cbe.org.eg, enterpriseam.com

Sheet Fixed Material Prices
A1: FIXED MATERIAL PRICES — EGYPT (3-MONTH AVERAGE, JUN–SEP 2026)
A2: Edit the Avg Price column (blue) if you have more current supplier quotations — all BOQ tabs update automatically
A4: Code | B4: Category | C4: Material Description | D4: Unit | E4: Avg Price (EGP) 3-mo avg | F4: Low | G4: High | H4: Confidence | I4: Source / Notes
A5: CEM-01 | B5: Cement | C5: Ordinary Portland Cement (OPC) – bulk/ex-factory | D5: ton | E5: 3800 | F5: 3600 | G5: 4000 | H5: Researched | I5: Egyptian Cement Co. official price list + multi-brand market surveys, Jun-Sep 2026
A6: CEM-02 | B6: Cement | C6: Sulphate Resistant Cement (SRC) | D6: ton | E6: 4300 | F6: 4050 | G6: 4550 | H6: Researched | I6: Egyptian Cement Co. official ex-works/consumer price list, Sep 2026
A7: CEM-03 | B7: Cement | C7: White Cement | D7: ton | E7: 5500 | F7: 5400 | G7: 6200 | H7: Researched | I7: Market price survey, Sep 2026
A8: STL-01 | B8: Steel | C8: Reinforcement Rebar – standard/local mills | D8: ton | E8: 36500 | F8: 33800 | G8: 38500 | H8: Researched | I8: Daily market price surveys across multiple mills, Jun-Sep 2026
A9: STL-02 | B9: Steel | C9: Reinforcement Rebar – premium brand (Ezz/Beshay) | D9: ton | E9: 39500 | F9: 39200 | G9: 40000 | H9: Researched | I9: Daily market price surveys, Jun-Sep 2026
A10: STL-03 | B10: Steel | C10: Structural/Misc. Steel Sections (bearings, brackets, ribs) | D10: ton | E10: 45000 | H10: Estimate – Verify | I10: Priced above rebar due to fabrication; confirm with steel fabricator
A11: AGG-01 | B11: Aggregates | C11: Backfill / Fill Sand | D11: m3 | E11: 150 | F11: 125 | G11: 270 | H11: Researched | I11: Market price survey, Sep 2026
A12: AGG-02 | B12: Aggregates | C12: Washed Concrete Sand (coarse) | D12: m3 | E12: 450 | F12: 405 | G12: 510 | H12: Researched | I12: Market price survey, Sep 2026
A13: AGG-03 | B13: Aggregates | C13: Gravel / Crushed Stone (dolomite) 3/4" | D13: m3 | E13: 450 | F13: 400 | G13: 570 | H13: Researched | I13: Market price survey, Sep 2026
A14: AGG-04 | B14: Aggregates | C14: Crushed Stone – Road Sub-base/Base Course | D14: m3 | E14: 420 | F14: 400 | G14: 560 | H14: Estimate – Verify | I14: Derived from AGG-03 survey range; confirm with quarry/supplier
A15: BRK-01 | B15: Masonry | C15: Red Perforated Clay Brick 25x12x12 cm | D15: 1000 units | E15: 5700 | F15: 4900 | G15: 6500 | H15: Researched | I15: Market price survey, Sep 2026
A16: BRK-02 | B16: Masonry | C16: Red Perforated Clay Brick 20x10x12 cm | D16: 1000 units | E16: 3500 | F16: 2750 | G16: 4200 | H16: Researched | I16: Market price survey, Sep 2026
A17: BLK-01 | B17: Masonry | C17: Solid Cement Block 20x10x6 cm | D17: 1000 units | E17: 5600 | H17: Estimate – Verify | I17: Derived from pallet pricing (~500 units/pallet), Mar 2026; confirm current
A18: BLK-02 | B18: Masonry | C18: Hollow Cement Block 40x20x20 cm | D18: 1000 units | E18: 45000 | H18: Estimate – Verify | I18: Derived from pallet pricing (~200 units/pallet), Mar 2026; confirm current
A19: FUEL-01 | B19: Fuel | C19: Diesel (Solar) – official pump price | D19: liter | E19: 20.5 | H19: Researched | I19: Ministry of Petroleum official price, frozen through Oct 2026
A20: FUEL-02 | B20: Fuel | C20: Gasoline 92 | D20: liter | E20: 22.25 | H20: Researched | I20: Ministry of Petroleum, Sep 2026
A21: FUEL-03 | B21: Fuel | C21: Gasoline 95 | D21: liter | E21: 24 | H21: Researched | I21: Ministry of Petroleum, Sep 2026
A22: FIN-01 | B22: Finishes | C22: Ceramic Floor/Wall Tiles (1st grade) | D22: m2 | E22: 250 | F22: 150 | G22: 350 | H22: Researched | I22: Market price survey, Sep 2026
A23: FIN-02 | B23: Finishes | C23: Plastic Paint (14-15 kg can) | D23: can | E23: 800 | F23: 480 | G23: 1200 | H23: Researched | I23: Market price survey, Sep 2026
A24: FIN-03 | B24: Finishes | C24: Putty / Filler (15 kg bag) | D24: bag | E24: 195 | H24: Researched | I24: Market price survey, Sep 2026
A25: RD-01 | B25: Bitumen/Asphalt | C25: Bitumen 60/70 (asphalt binder) | D25: ton | E25: 19000 | H25: Estimate – Verify | I25: Petroleum Authority price adjusted periodically; obtain current supplier quote
A26: RD-02 | B26: Bitumen/Asphalt | C26: Hot Mix Asphalt, laid (binder+wearing course) | D26: ton | E26: 8500 | H26: Estimate – Verify | I26: Includes bitumen+aggregate+plant+laying; confirm with asphalt plant/subcontractor
A27: TBR-01 | B27: Formwork | C27: Plywood/Formica Formwork Board, 18mm (contact area) | D27: m2 | E27: 900 | H27: Estimate – Verify | I27: Confirm with timber supplier; amortize over ~4-6 reuse cycles (see Thresholds sheet)
A28: ADM-01 | B28: Admixture | C28: Concrete Admixture (plasticizer/superplasticizer) | D28: per m3 concrete | E28: 40 | H28: Estimate – Verify | I28: Typical allowance; confirm with chemical admixture supplier
A29: WTP-01 | B29: Waterproofing | C29: Waterproofing Membrane (torch-applied/sheet) | D29: m2 | E29: 220 | F29: 150 | G29: 350 | H29: Estimate – Verify | I29: Market range depends on system; confirm with specialist supplier
A30: CONC-C15 | B30: Concrete (computed) | C30: Blinding / Lean Concrete C15 | D30: m3 | E30: ='Concrete Mix Calculator'!$K$5 -> 1970 | H30: Computed | I30: Concrete Mix Calculator sheet — dynamic, driven by Cement/Sand/Gravel prices above
A31: CONC-C20 | B31: Concrete (computed) | C31: Structural Concrete C20 | D31: m3 | E31: ='Concrete Mix Calculator'!$K$6 -> 2133 | H31: Computed | I31: Concrete Mix Calculator sheet — dynamic, driven by Cement/Sand/Gravel prices above
A32: CONC-C25 | B32: Concrete (computed) | C32: Structural Concrete C25 | D32: m3 | E32: ='Concrete Mix Calculator'!$K$7 -> 2296 | H32: Computed | I32: Concrete Mix Calculator sheet — dynamic, driven by Cement/Sand/Gravel prices above
A33: CONC-C30 | B33: Concrete (computed) | C33: Structural Concrete C30 | D33: m3 | E33: ='Concrete Mix Calculator'!$K$8 -> 2387.5 | H33: Computed | I33: Concrete Mix Calculator sheet — dynamic, driven by Cement/Sand/Gravel prices above
A34: CONC-C35 | B34: Concrete (computed) | C34: Structural Concrete C35 | D34: m3 | E34: ='Concrete Mix Calculator'!$K$9 -> 2445.5 | H34: Computed | I34: Concrete Mix Calculator sheet — dynamic, driven by Cement/Sand/Gravel prices above
A35: CONC-C40 | B35: Concrete (computed) | C35: Structural Concrete C40 (bridges/heavy) | D35: m3 | E35: ='Concrete Mix Calculator'!$K$10 -> 2522.5 | H35: Computed | I35: Concrete Mix Calculator sheet — dynamic, driven by Cement/Sand/Gravel prices above
A36: CONC-C45 | B36: Concrete (computed) | C36: Structural Concrete C45 (bridges, high strength) | D36: m3 | E36: ='Concrete Mix Calculator'!$K$11 -> 2599.5 | H36: Computed | I36: Concrete Mix Calculator sheet — dynamic, driven by Cement/Sand/Gravel prices above
A37: CONC-C50 | B37: Concrete (computed) | C37: Structural Concrete C50 (pre-stressed elements) | D37: m3 | E37: ='Concrete Mix Calculator'!$K$12 -> 2676.5 | H37: Computed | I37: Concrete Mix Calculator sheet — dynamic, driven by Cement/Sand/Gravel prices above

Sheet Concrete Mix Calculator
A1: CONCRETE MIX DESIGN COST CALCULATOR
A2: Indicative mix ratios per typical Egyptian RC practice — confirm with approved trial mix / lab report per project
A4: Grade | B4: Description | C4: Cement (kg/m3) | D4: Sand (m3/m3) | E4: Gravel (m3/m3) | F4: Cement Cost (EGP/m3) | G4: Sand Cost (EGP/m3) | H4: Gravel Cost (EGP/m3) | I4: Admixture Allowance (EGP/m3) | J4: Batching/Mixing/ Pumping (EGP/m3) | K4: TOTAL COST per m3 (EGP)
A5: C15 | B5: Blinding / Lean Concrete | C5: 250 | D5: 0.55 | E5: 0.85 | F5: =C5/1000*'Fixed Material Prices'!$E$5 -> 950 | G5: =D5*'Fixed Material Prices'!$E$12 -> 247.5 | H5: =E5*'Fixed Material Prices'!$E$13 -> 382.5 | I5: ='Fixed Material Prices'!$E$28 -> 40 | J5: 350 | K5: =SUM(F5:J5) -> 1970
A6: C20 | B6: Structural Concrete C20 | C6: 300 | D6: 0.52 | E6: 0.82 | F6: =C6/1000*'Fixed Material Prices'!$E$5 -> 1140 | G6: =D6*'Fixed Material Prices'!$E$12 -> 234 | H6: =E6*'Fixed Material Prices'!$E$13 -> 369 | I6: ='Fixed Material Prices'!$E$28 -> 40 | J6: 350 | K6: =SUM(F6:J6) -> 2133
A7: C25 | B7: Structural Concrete C25 | C7: 350 | D7: 0.48 | E7: 0.8 | F7: =C7/1000*'Fixed Material Prices'!$E$5 -> 1330 | G7: =D7*'Fixed Material Prices'!$E$12 -> 216 | H7: =E7*'Fixed Material Prices'!$E$13 -> 360 | I7: ='Fixed Material Prices'!$E$28 -> 40 | J7: 350 | K7: =SUM(F7:J7) -> 2296
A8: C30 | B8: Structural Concrete C30 | C8: 380 | D8: 0.45 | E8: 0.78 | F8: =C8/1000*'Fixed Material Prices'!$E$5 -> 1444 | G8: =D8*'Fixed Material Prices'!$E$12 -> 202.5 | H8: =E8*'Fixed Material Prices'!$E$13 -> 351 | I8: ='Fixed Material Prices'!$E$28 -> 40 | J8: 350 | K8: =SUM(F8:J8) -> 2387.5
A9: C35 | B9: Structural Concrete C35 | C9: 400 | D9: 0.43 | E9: 0.76 | F9: =C9/1000*'Fixed Material Prices'!$E$5 -> 1520 | G9: =D9*'Fixed Material Prices'!$E$12 -> 193.5 | H9: =E9*'Fixed Material Prices'!$E$13 -> 342 | I9: ='Fixed Material Prices'!$E$28 -> 40 | J9: 350 | K9: =SUM(F9:J9) -> 2445.5
A10: C40 | B10: Structural Concrete C40 | C10: 425 | D10: 0.4 | E10: 0.75 | F10: =C10/1000*'Fixed Material Prices'!$E$5 -> 1615 | G10: =D10*'Fixed Material Prices'!$E$12 -> 180 | H10: =E10*'Fixed Material Prices'!$E$13 -> 337.5 | I10: ='Fixed Material Prices'!$E$28 -> 40 | J10: 350 | K10: =SUM(F10:J10) -> 2522.5
A11: C45 | B11: Structural Concrete C45 (bridges) | C11: 450 | D11: 0.38 | E11: 0.73 | F11: =C11/1000*'Fixed Material Prices'!$E$5 -> 1710 | G11: =D11*'Fixed Material Prices'!$E$12 -> 171 | H11: =E11*'Fixed Material Prices'!$E$13 -> 328.5 | I11: ='Fixed Material Prices'!$E$28 -> 40 | J11: 350 | K11: =SUM(F11:J11) -> 2599.5
A12: C50 | B12: Structural Concrete C50 (pre-stressed) | C12: 475 | D12: 0.36 | E12: 0.71 | F12: =C12/1000*'Fixed Material Prices'!$E$5 -> 1805 | G12: =D12*'Fixed Material Prices'!$E$12 -> 162 | H12: =E12*'Fixed Material Prices'!$E$13 -> 319.5 | I12: ='Fixed Material Prices'!$E$28 -> 40 | J12: 350 | K12: =SUM(F12:J12) -> 2676.5
A14: Mix ratios are indicative planning figures (typical Egyptian practice for normal-weight structural concrete) — the actual mix design must be confirmed by an approved trial mix / laboratory report for the specific project, cement type and target slump. Batching/Mixing/Pumping (col J) and Admixture allowance (col I, linked to ADM-01) are editable per project/plant arrangement.

Sheet Labor & Equipment Rates
A1: LABOR & EQUIPMENT RATES — REFERENCE
A2: Adjust to your own crew wages / owned or rented plant rates — used as reference when pricing BOQ items
A4: LABOR (DAILY WAGE RATES, EGP)
A5: Code | B5: Trade | C5: Unit | D5: Low (EGP) | E5: High (EGP) | F5: Avg / Used (EGP) | G5: Source / Notes
A6: LAB-01 | B6: Skilled Steel Fixer (Haddad) | C6: day | D6: 1000 | E6: 1700 | F6: 1350 | G6: Aqaar24 daily labor wage survey, 2026
A7: LAB-02 | B7: Steel Fixer Assistant | C7: day | D7: 600 | E7: 900 | F7: 750 | G7: Aqaar24 daily labor wage survey, 2026
A8: LAB-03 | B8: Skilled Carpenter (Naggar) | C8: day | D8: 900 | E8: 1500 | F8: 1200 | G8: Aqaar24 daily labor wage survey, 2026
A9: LAB-04 | B9: Carpenter Assistant | C9: day | D9: 500 | E9: 800 | F9: 650 | G9: Aqaar24 daily labor wage survey, 2026
A10: LAB-05 | B10: Skilled Painter | C10: day | D10: 800 | E10: 1400 | F10: 1100 | G10: Aqaar24 daily labor wage survey, 2026
A11: LAB-06 | B11: Painter Assistant | C11: day | D11: 400 | E11: 700 | F11: 550 | G11: Aqaar24 daily labor wage survey, 2026
A12: LAB-07 | B12: Mason / Bricklayer (skilled) | C12: day | D12: 900 | E12: 1400 | F12: 1150 | G12: Estimate – verify locally, comparable trade rate
A13: LAB-08 | B13: General Laborer | C13: day | D13: 400 | E13: 650 | F13: 525 | G13: Estimate – verify locally
A14: LAB-09 | B14: Foreman / Site Supervisor | C14: day | D14: 1500 | E14: 2500 | F14: 2000 | G14: Estimate – verify locally
A15: LAB-10 | B15: Site Engineer (junior/resident) | C15: month | D15: 15000 | E15: 25000 | F15: 20000 | G15: Estimate – verify locally
A17: EQUIPMENT & PLANT (RENTAL RATES — HIGHLY VARIABLE, INSERT ACTUAL QUOTES)
A18: Code | B18: Equipment | C18: Unit | D18: Low (EGP) | E18: High (EGP) | F18: Avg / Used (EGP) | G18: Source / Notes
A19: EQP-01 | B19: Excavator (medium, ~21-30T) | C19: day | D19: 3000 | E19: 6000 | F19: 4500 | G19: Indicative market range – obtain rental/owning-cost quote
A20: EQP-02 | B20: Concrete Pump (mobile boom) | C20: day | D20: 8000 | E20: 15000 | F20: 11500 | G20: Indicative market range – obtain rental quote
A21: EQP-03 | B21: Tower Crane | C21: month | D21: 60000 | E21: 120000 | F21: 90000 | G21: Indicative market range – obtain rental quote
A22: EQP-04 | B22: Dump Truck (10 m3, incl. fuel & driver) | C22: day | D22: 3500 | E22: 6000 | F22: 4750 | G22: Indicative market range – obtain rental quote
A23: EQP-05 | B23: Bulldozer | C23: day | D23: 4000 | E23: 7000 | F23: 5500 | G23: Indicative market range – obtain rental quote
A24: EQP-06 | B24: Vibratory Roller / Compactor (roads) | C24: day | D24: 3000 | E24: 5500 | F24: 4250 | G24: Indicative market range – obtain rental quote
A25: EQP-07 | B25: Piling Rig (bored piles, bridges) | C25: day/shift | D25: 25000 | E25: 50000 | F25: 37500 | G25: Specialized plant — obtain project-specific quote
A26: EQP-08 | B26: TBM / Roadheader (tunnels) | C26: day/shift | D26: 0 | E26: 0 | F26: 0 | G26: Highly project-specific — obtain dedicated supplier/subcontractor quote
A27: EQP-09 | B27: Standby Generator | C27: day | D27: 1500 | E27: 3000 | F27: 2250 | G27: Indicative market range – obtain rental quote

Sheet Thresholds & Assumptions
A1: THRESHOLDS & COMMERCIAL ASSUMPTIONS
A2: Review and adjust every yellow cell before finalizing any bid — all figures below feed the Bid Summary Dashboard
A4: 1. RISK-BASED CONTINGENCY MATRIX
A5: Risk Level | B5: Contingency % Applied | D5: Typical Use / Basis
A6: Low | B6: 0.03 | D6: Repetitive, well-defined scope, firm BOQ, familiar site — e.g. standard buildings, minor resurfacing
A7: Medium | B7: 0.06 | D7: Some design/ground uncertainty, moderate site risk — e.g. new roads, standard bridges
A8: High | B8: 0.1 | D8: Significant uncertainty, difficult ground/logistics — e.g. complex bridges, large/urban infrastructure
A9: Very High | B9: 0.15 | D9: Major unknowns, specialized/first-of-kind works — e.g. tunnels, deep foundations, marine works
A11: 2. OVERHEAD RATES (% of Direct Cost)
A12: Overhead Type | B12: Rate Applied
A13: Site (Field) Overhead % | B13: 0.1 | C13: Site staff, temporary facilities, utilities, site supervision, security
A14: Head Office Overhead % | B14: 0.06 | C14: HQ admin & staff apportionment, corporate insurance, central costs
A16: 3. PROFIT MARGIN THRESHOLDS (% of Cost, by Project Type)
A17: Project Type | B17: Min. Acceptable Margin | C17: Target Margin | D17: Max. Competitive Margin
A18: Buildings | B18: 0.06 | C18: 0.1 | D18: 0.15
A19: Roads | B19: 0.05 | C19: 0.08 | D19: 0.12
A20: Bridges | B20: 0.07 | C20: 0.12 | D20: 0.18
A21: Tunnels | B21: 0.1 | C21: 0.15 | D21: 0.22
A23: 4. PRICE ESCALATION / INFLATION ASSUMPTIONS
A24: Item | B24: Value
A25: Assumed Annual Escalation Rate (materials & labor) | B25: 0.15 | C25: Based on CAPMAS urban inflation ~14.5% (Aug 2026) plus a construction-specific premium
A26: Project Duration (months) | B26: 12 | C26: Set per specific tender
A27: Escalation Allowance % (applied to direct cost) | B27: =B25*(B26/12)*0.5 -> 0.075 | C27: Assumes even cost incidence over duration (avg. 50% exposure). Replace with the contract's own index-linked price-adjustment formula (e.g. FIDIC/local Pn=Po(a+b·Mn/Mo+c·Ln/Lo)) if one is stipulated.
A29: 5. BONDS, GUARANTEES & RETENTION
A30: Item | B30: Rate
A31: Bid Bond | B31: 0.015 | C31: % of estimated contract value, returned after contract award
A32: Performance Bond | B32: 0.05 | C32: % of contract value, held for contract duration
A33: Advance Payment (received) | B33: 0.15 | C33: % of contract value, secured by an Advance Payment Guarantee
A34: Advance Payment Guarantee (APG) | B34: 0.15 | C34: Matches advance payment %; reduces as the advance is recovered from IPCs
A35: Retention Money | B35: 0.05 | C35: Withheld from each payment certificate; released 50% at Taking-Over, 50% after DLP
A36: Bank Guarantee Commission (p.a.) | B36: 0.02 | C36: Annual commission charged by the bank on outstanding guarantees — a real contractor cost
A38: 6. INSURANCE
A39: Type | B39: Rate
A40: Contractor's All Risk (CAR) | B40: 0.004 | C40: % of contract value
A41: Third Party Liability (TPL) | B41: 0.0015 | C41: % of contract value
A42: Workmen's Compensation / Social Insurance | B42: 0.015 | C42: % of total labor cost
A44: 7. TAXES & STATUTORY DEDUCTIONS
A45: Item | B45: Rate
A46: VAT (Value Added Tax) | B46: 0.14 | C46: Standard Egyptian VAT rate, added on top of contract price
A47: Withholding Tax (advance against income tax) | B47: 0.03 | C47: Deducted by employer from each payment; a cash-flow timing effect, not a bid-price addition
...

Sheet BOQ - Buildings
A1: BOQ - BUILDINGS — BILL OF QUANTITIES & PRICING BUILD-UP
A2: Enter quantities and pick Material Codes from the dropdown — unit prices pull live from Fixed Material Prices
A4: Item | B4: Description | C4: Unit | D4: Quantity | E4: Material Code | F4: Material Unit Price (EGP) | G4: Wastage % | H4: Material Cost /Unit (EGP) | I4: Labor Cost /Unit (EGP) | J4: Equipment Cost /Unit (EGP) | K4: Subcontractor Rate/Unit (EGP) | L4: Direct Unit Rate (EGP) | M4: Amount (EGP) | N4: Notes
A5: A. PRELIMINARIES & GENERAL
A6: 1 | B6: Mobilization & Demobilization | C6: LS | D6: 0 | F6: =IF($E6="","",IFERROR(INDEX(MaterialPrices,MATCH($E6,MaterialCodes,0)),0)) | G6: 0 | H6: =IF($F6="",0,$F6*(1+$G6)) -> 0 | I6: 0 | J6: 0 | K6: 0 | L6: =H6+I6+J6+K6 -> 0 | M6: =D6*L6 -> 0
A7: 2 | B7: Site Establishment (offices, stores, temp. fencing) | C7: LS | D7: 0 | F7: =IF($E7="","",IFERROR(INDEX(MaterialPrices,MATCH($E7,MaterialCodes,0)),0)) | G7: 0 | H7: =IF($F7="",0,$F7*(1+$G7)) -> 0 | I7: 0 | J7: 0 | K7: 0 | L7: =H7+I7+J7+K7 -> 0 | M7: =D7*L7 -> 0
A8: 3 | B8: Survey & Setting Out | C8: LS | D8: 0 | F8: =IF($E8="","",IFERROR(INDEX(MaterialPrices,MATCH($E8,MaterialCodes,0)),0)) | G8: 0 | H8: =IF($F8="",0,$F8*(1+$G8)) -> 0 | I8: 0 | J8: 0 | K8: 0 | L8: =H8+I8+J8+K8 -> 0 | M8: =D8*L8 -> 0
A9: 4 | B9: Site Safety & HSE Provisions | C9: LS | D9: 0 | F9: =IF($E9="","",IFERROR(INDEX(MaterialPrices,MATCH($E9,MaterialCodes,0)),0)) | G9: 0 | H9: =IF($F9="",0,$F9*(1+$G9)) -> 0 | I9: 0 | J9: 0 | K9: 0 | L9: =H9+I9+J9+K9 -> 0 | M9: =D9*L9 -> 0
A10: Subtotal — A. PRELIMINARIES & GENERAL | M10: =SUM(M6:M9) -> 0
A11: B. EARTHWORKS & SUBSTRUCTURE
A12: 5 | B12: Excavation for Foundations | C12: m3 | D12: 0 | F12: =IF($E12="","",IFERROR(INDEX(MaterialPrices,MATCH($E12,MaterialCodes,0)),0)) | G12: 0 | H12: =IF($F12="",0,$F12*(1+$G12)) -> 0 | I12: 0 | J12: 0 | K12: 0 | L12: =H12+I12+J12+K12 -> 0 | M12: =D12*L12 -> 0
A13: 6 | B13: Backfilling & Compaction | C13: m3 | D13: 0 | E13: AGG-01 | F13: =IF($E13="","",IFERROR(INDEX(MaterialPrices,MATCH($E13,MaterialCodes,0)),0)) -> 150 | G13: ='Thresholds & Assumptions'!$B$55 -> 0.05 | H13: =IF($F13="",0,$F13*(1+$G13)) -> 157.5 | I13: 0 | J13: 0 | K13: 0 | L13: =H13+I13+J13+K13 -> 157.5 | M13: =D13*L13 -> 0
A14: 7 | B14: Blinding Concrete (C15) | C14: m3 | D14: 0 | E14: CONC-C15 | F14: =IF($E14="","",IFERROR(INDEX(MaterialPrices,MATCH($E14,MaterialCodes,0)),0)) -> 1970 | G14: ='Thresholds & Assumptions'!$B$53 -> 0.02 | H14: =IF($F14="",0,$F14*(1+$G14)) -> 2009.4 | I14: 0 | J14: 0 | K14: 0 | L14: =H14+I14+J14+K14 -> 2009.4 | M14: =D14*L14 -> 0
A15: 8 | B15: Foundation Concrete – Footings/Raft (C30) | C15: m3 | D15: 0 | E15: CONC-C30 | F15: =IF($E15="","",IFERROR(INDEX(MaterialPrices,MATCH($E15,MaterialCodes,0)),0)) -> 2387.5 | G15: ='Thresholds & Assumptions'!$B$53 -> 0.02 | H15: =IF($F15="",0,$F15*(1+$G15)) -> 2435.25 | I15: 0 | J15: 0 | K15: 0 | L15: =H15+I15+J15+K15 -> 2435.25 | M15: =D15*L15 -> 0
A16: 9 | B16: Reinforcement Steel – Foundations | C16: ton | D16: 0 | E16: STL-01 | F16: =IF($E16="","",IFERROR(INDEX(MaterialPrices,MATCH($E16,MaterialCodes,0)),0)) -> 36500 | G16: ='Thresholds & Assumptions'!$B$52 -> 0.03 | H16: =IF($F16="",0,$F16*(1+$G16)) -> 37595 | I16: 0 | J16: 0 | K16: 0 | L16: =H16+I16+J16+K16 -> 37595 | M16: =D16*L16 -> 0
A17: 10 | B17: Formwork – Foundations | C17: m2 | D17: 0 | E17: TBR-01 | F17: =IF($E17="","",IFERROR(INDEX(MaterialPrices,MATCH($E17,MaterialCodes,0)),0)) -> 900 | G17: ='Thresholds & Assumptions'!$B$57 -> 0.2 | H17: =IF($F17="",0,$F17*(1+$G17)) -> 1080 | I17: 0 | J17: 0 | K17: 0 | L17: =H17+I17+J17+K17 -> 1080 | M17: =D17*L17 -> 0
A18: 11 | B18: Waterproofing Membrane – Foundations | C18: m2 | D18: 0 | E18: WTP-01 | F18: =IF($E18="","",IFERROR(INDEX(MaterialPrices,MATCH($E18,MaterialCodes,0)),0)) -> 220 | G18: 0 | H18: =IF($F18="",0,$F18*(1+$G18)) -> 220 | I18: 0 | J18: 0 | K18: 0 | L18: =H18+I18+J18+K18 -> 220 | M18: =D18*L18 -> 0
A19: Subtotal — B. EARTHWORKS & SUBSTRUCTURE | M19: =SUM(M12:M18) -> 0
A20: C. SUPERSTRUCTURE – CONCRETE FRAME
A21: 12 | B21: Columns Concrete (C30) | C21: m3 | D21: 0 | E21: CONC-C30 | F21: =IF($E21="","",IFERROR(INDEX(MaterialPrices,MATCH($E21,MaterialCodes,0)),0)) -> 2387.5 | G21: ='Thresholds & Assumptions'!$B$53 -> 0.02 | H21: =IF($F21="",0,$F21*(1+$G21)) -> 2435.25 | I21: 0 | J21: 0 | K21: 0 | L21: =H21+I21+J21+K21 -> 2435.25 | M21: =D21*L21 -> 0
A22: 13 | B22: Columns Reinforcement | C22: ton | D22: 0 | E22: STL-01 | F22: =IF($E22="","",IFERROR(INDEX(MaterialPrices,MATCH($E22,MaterialCodes,0)),0)) -> 36500 | G22: ='Thresholds & Assumptions'!$B$52 -> 0.03 | H22: =IF($F22="",0,$F22*(1+$G22)) -> 37595 | I22: 0 | J22: 0 | K22: 0 | L22: =H22+I22+J22+K22 -> 37595 | M22: =D22*L22 -> 0
A23: 14 | B23: Columns Formwork | C23: m2 | D23: 0 | E23: TBR-01 | F23: =IF($E23="","",IFERROR(INDEX(MaterialPrices,MATCH($E23,MaterialCodes,0)),0)) -> 900 | G23: ='Thresholds & Assumptions'!$B$57 -> 0.2 | H23: =IF($F23="",0,$F23*(1+$G23)) -> 1080 | I23: 0 | J23: 0 | K23: 0 | L23: =H23+I23+J23+K23 -> 1080 | M23: =D23*L23 -> 0
A24: 15 | B24: Beams & Slabs Concrete (C30) | C24: m3 | D24: 0 | E24: CONC-C30 | F24: =IF($E24="","",IFERROR(INDEX(MaterialPrices,MATCH($E24,MaterialCodes,0)),0)) -> 2387.5 | G24: ='Thresholds & Assumptions'!$B$53 -> 0.02 | H24: =IF($F24="",0,$F24*(1+$G24)) -> 2435.25 | I24: 0 | J24: 0 | K24: 0 | L24: =H24+I24+J24+K24 -> 2435.25 | M24: =D24*L24 -> 0
A25: 16 | B25: Beams & Slabs Reinforcement | C25: ton | D25: 0 | E25: STL-01 | F25: =IF($E25="","",IFERROR(INDEX(MaterialPrices,MATCH($E25,MaterialCodes,0)),0)) -> 36500 | G25: ='Thresholds & Assumptions'!$B$52 -> 0.03 | H25: =IF($F25="",0,$F25*(1+$G25)) -> 37595 | I25: 0 | J25: 0 | K25: 0 | L25: =H25+I25+J25+K25 -> 37595 | M25: =D25*L25 -> 0
A26: 17 | B26: Beams & Slabs Formwork | C26: m2 | D26: 0 | E26: TBR-01 | F26: =IF($E26="","",IFERROR(INDEX(MaterialPrices,MATCH($E26,MaterialCodes,0)),0)) -> 900 | G26: ='Thresholds & Assumptions'!$B$57 -> 0.2 | H26: =IF($F26="",0,$F26*(1+$G26)) -> 1080 | I26: 0 | J26: 0 | K26: 0 | L26: =H26+I26+J26+K26 -> 1080 | M26: =D26*L26 -> 0
A27: 18 | B27: Staircases (Concrete + Reinforcement) | C27: m3 | D27: 0 | E27: CONC-C30 | F27: =IF($E27="","",IFERROR(INDEX(MaterialPrices,MATCH($E27,MaterialCodes,0)),0)) -> 2387.5 | G27: ='Thresholds & Assumptions'!$B$53 -> 0.02 | H27: =IF($F27="",0,$F27*(1+$G27)) -> 2435.25 | I27: 0 | J27: 0 | K27: 0 | L27: =H27+I27+J27+K27 -> 2435.25 | M27: =D27*L27 -> 0
A28: Subtotal — C. SUPERSTRUCTURE – CONCRETE FRAME | M28: =SUM(M21:M27) -> 0
A29: D. MASONRY & WALLS
A30: 19 | B30: External Walls – Red Brick 25 cm | C30: m2 | D30: 0 | E30: BRK-01 | F30: =IF($E30="","",IFERROR(INDEX(MaterialPrices,MATCH($E30,MaterialCodes,0)),0)) -> 5700 | G30: ='Thresholds & Assumptions'!$B$54 -> 0.05 | H30: =IF($F30="",0,$F30*(1+$G30)) -> 5985 | I30: 0 | J30: 0 | K30: 0 | L30: =H30+I30+J30+K30 -> 5985 | M30: =D30*L30 -> 0
A31: 20 | B31: Internal Partitions – Brick 12 cm | C31: m2 | D31: 0 | E31: BRK-02 | F31: =IF($E31="","",IFERROR(INDEX(MaterialPrices,MATCH($E31,MaterialCodes,0)),0)) -> 3500 | G31: ='Thresholds & Assumptions'!$B$54 -> 0.05 | H31: =IF($F31="",0,$F31*(1+$G31)) -> 3675 | I31: 0 | J31: 0 | K31: 0 | L31: =H31+I31+J31+K31 -> 3675 | M31: =D31*L31 -> 0
A32: 21 | B32: Internal Plastering | C32: m2 | D32: 0 | F32: =IF($E32="","",IFERROR(INDEX(MaterialPrices,MATCH($E32,MaterialCodes,0)),0)) | G32: 0 | H32: =IF($F32="",0,$F32*(1+$G32)) -> 0 | I32: 0 | J32: 0 | K32: 0 | L32: =H32+I32+J32+K32 -> 0 | M32: =D32*L32 -> 0
A33: 22 | B33: External Plastering | C33: m2 | D33: 0 | F33: =IF($E33="","",IFERROR(INDEX(MaterialPrices,MATCH($E33,MaterialCodes,0)),0)) | G33: 0 | H33: =IF($F33="",0,$F33*(1+$G33)) -> 0 | I33: 0 | J33: 0 | K33: 0 | L33: =H33+I33+J33+K33 -> 0 | M33: =D33*L33 -> 0
A34: Subtotal — D. MASONRY & WALLS | M34: =SUM(M30:M33) -> 0
A35: E. FINISHES
A36: 23 | B36: Floor Tiling – Ceramic | C36: m2 | D36: 0 | E36: FIN-01 | F36: =IF($E36="","",IFERROR(INDEX(MaterialPrices,MATCH($E36,MaterialCodes,0)),0)) -> 250 | G36: ='Thresholds & Assumptions'!$B$56 -> 0.08 | H36: =IF($F36="",0,$F36*(1+$G36)) -> 270 | I36: 0 | J36: 0 | K36: 0 | L36: =H36+I36+J36+K36 -> 270 | M36: =D36*L36 -> 0
A37: 24 | B37: Wall Tiling | C37: m2 | D37: 0 | E37: FIN-01 | F37: =IF($E37="","",IFERROR(INDEX(MaterialPrices,MATCH($E37,MaterialCodes,0)),0)) -> 250 | G37: ='Thresholds & Assumptions'!$B$56 -> 0.08 | H37: =IF($F37="",0,$F37*(1+$G37)) -> 270 | I37: 0 | J37: 0 | K37: 0 | L37: =H37+I37+J37+K37 -> 270 | M37: =D37*L37 -> 0
A38: 25 | B38: Internal Painting | C38: m2 | D38: 0 | E38: FIN-02 | F38: =IF($E38="","",IFERROR(INDEX(MaterialPrices,MATCH($E38,MaterialCodes,0)),0)) -> 800 | G38: ='Thresholds & Assumptions'!$B$58 -> 0.05 | H38: =IF($F38="",0,$F38*(1+$G38)) -> 840 | I38: 0 | J38: 0 | K38: 0 | L38: =H38+I38+J38+K38 -> 840 | M38: =D38*L38 -> 0
A39: 26 | B39: External Painting | C39: m2 | D39: 0 | E39: FIN-02 | F39: =IF($E39="","",IFERROR(INDEX(MaterialPrices,MATCH($E39,MaterialCodes,0)),0)) -> 800 | G39: ='Thresholds & Assumptions'!$B$58 -> 0.05 | H39: =IF($F39="",0,$F39*(1+$G39)) -> 840 | I39: 0 | J39: 0 | K39: 0 | L39: =H39+I39+J39+K39 -> 840 | M39: =D39*L39 -> 0
A40: 27 | B40: Doors & Windows (Aluminum/Wood) | C40: m2 | D40: 0 | F40: =IF($E40="","",IFERROR(INDEX(MaterialPrices,MATCH($E40,MaterialCodes,0)),0)) | G40: 0 | H40: =IF($F40="",0,$F40*(1+$G40)) -> 0 | I40: 0 | J40: 0 | K40: 0 | L40: =H40+I40+J40+K40 -> 0 | M40: =D40*L40 -> 0
A41: 28 | B41: False Ceiling | C41: m2 | D41: 0 | F41: =IF($E41="","",IFERROR(INDEX(MaterialPrices,MATCH($E41,MaterialCodes,0)),0)) | G41: 0 | H41: =IF($F41="",0,$F41*(1+$G41)) -> 0 | I41: 0 | J41: 0 | K41: 0 | L41: =H41+I41+J41+K41 -> 0 | M41: =D41*L41 -> 0
...

Sheet BOQ - Roads
A1: BOQ - ROADS — BILL OF QUANTITIES & PRICING BUILD-UP
A2: Enter quantities and pick Material Codes from the dropdown — unit prices pull live from Fixed Material Prices
A4: Item | B4: Description | C4: Unit | D4: Quantity | E4: Material Code | F4: Material Unit Price (EGP) | G4: Wastage % | H4: Material Cost /Unit (EGP) | I4: Labor Cost /Unit (EGP) | J4: Equipment Cost /Unit (EGP) | K4: Subcontractor Rate/Unit (EGP) | L4: Direct Unit Rate (EGP) | M4: Amount (EGP) | N4: Notes
A5: A. PRELIMINARIES
A6: 1 | B6: Mobilization, Traffic Diversion & Signage | C6: LS | D6: 0 | F6: =IF($E6="","",IFERROR(INDEX(MaterialPrices,MATCH($E6,MaterialCodes,0)),0)) | G6: 0 | H6: =IF($F6="",0,$F6*(1+$G6)) -> 0 | I6: 0 | J6: 0 | K6: 0 | L6: =H6+I6+J6+K6 -> 0 | M6: =D6*L6 -> 0
A7: 2 | B7: Survey & Setting Out | C7: LS | D7: 0 | F7: =IF($E7="","",IFERROR(INDEX(MaterialPrices,MATCH($E7,MaterialCodes,0)),0)) | G7: 0 | H7: =IF($F7="",0,$F7*(1+$G7)) -> 0 | I7: 0 | J7: 0 | K7: 0 | L7: =H7+I7+J7+K7 -> 0 | M7: =D7*L7 -> 0
A8: Subtotal — A. PRELIMINARIES | M8: =SUM(M6:M7) -> 0
A9: B. EARTHWORKS
A10: 3 | B10: Site Clearance & Grubbing | C10: m2 | D10: 0 | F10: =IF($E10="","",IFERROR(INDEX(MaterialPrices,MATCH($E10,MaterialCodes,0)),0)) | G10: 0 | H10: =IF($F10="",0,$F10*(1+$G10)) -> 0 | I10: 0 | J10: 0 | K10: 0 | L10: =H10+I10+J10+K10 -> 0 | M10: =D10*L10 -> 0
A11: 4 | B11: Excavation (Cut) | C11: m3 | D11: 0 | F11: =IF($E11="","",IFERROR(INDEX(MaterialPrices,MATCH($E11,MaterialCodes,0)),0)) | G11: 0 | H11: =IF($F11="",0,$F11*(1+$G11)) -> 0 | I11: 0 | J11: 0 | K11: 0 | L11: =H11+I11+J11+K11 -> 0 | M11: =D11*L11 -> 0
A12: 5 | B12: Embankment Fill & Compaction | C12: m3 | D12: 0 | E12: AGG-01 | F12: =IF($E12="","",IFERROR(INDEX(MaterialPrices,MATCH($E12,MaterialCodes,0)),0)) -> 150 | G12: ='Thresholds & Assumptions'!$B$55 -> 0.05 | H12: =IF($F12="",0,$F12*(1+$G12)) -> 157.5 | I12: 0 | J12: 0 | K12: 0 | L12: =H12+I12+J12+K12 -> 157.5 | M12: =D12*L12 -> 0
A13: 6 | B13: Subgrade Preparation & Compaction | C13: m2 | D13: 0 | F13: =IF($E13="","",IFERROR(INDEX(MaterialPrices,MATCH($E13,MaterialCodes,0)),0)) | G13: 0 | H13: =IF($F13="",0,$F13*(1+$G13)) -> 0 | I13: 0 | J13: 0 | K13: 0 | L13: =H13+I13+J13+K13 -> 0 | M13: =D13*L13 -> 0
A14: Subtotal — B. EARTHWORKS | M14: =SUM(M10:M13) -> 0
A15: C. PAVEMENT LAYERS
A16: 7 | B16: Sub-base Course (Crushed Stone) | C16: m3 | D16: 0 | E16: AGG-04 | F16: =IF($E16="","",IFERROR(INDEX(MaterialPrices,MATCH($E16,MaterialCodes,0)),0)) -> 420 | G16: ='Thresholds & Assumptions'!$B$55 -> 0.05 | H16: =IF($F16="",0,$F16*(1+$G16)) -> 441 | I16: 0 | J16: 0 | K16: 0 | L16: =H16+I16+J16+K16 -> 441 | M16: =D16*L16 -> 0
A17: 8 | B17: Base Course (Crushed Stone) | C17: m3 | D17: 0 | E17: AGG-04 | F17: =IF($E17="","",IFERROR(INDEX(MaterialPrices,MATCH($E17,MaterialCodes,0)),0)) -> 420 | G17: ='Thresholds & Assumptions'!$B$55 -> 0.05 | H17: =IF($F17="",0,$F17*(1+$G17)) -> 441 | I17: 0 | J17: 0 | K17: 0 | L17: =H17+I17+J17+K17 -> 441 | M17: =D17*L17 -> 0
A18: 9 | B18: Prime Coat | C18: m2 | D18: 0 | E18: RD-01 | F18: =IF($E18="","",IFERROR(INDEX(MaterialPrices,MATCH($E18,MaterialCodes,0)),0)) -> 19000 | G18: 0 | H18: =IF($F18="",0,$F18*(1+$G18)) -> 19000 | I18: 0 | J18: 0 | K18: 0 | L18: =H18+I18+J18+K18 -> 19000 | M18: =D18*L18 -> 0
A19: 10 | B19: Tack Coat | C19: m2 | D19: 0 | E19: RD-01 | F19: =IF($E19="","",IFERROR(INDEX(MaterialPrices,MATCH($E19,MaterialCodes,0)),0)) -> 19000 | G19: 0 | H19: =IF($F19="",0,$F19*(1+$G19)) -> 19000 | I19: 0 | J19: 0 | K19: 0 | L19: =H19+I19+J19+K19 -> 19000 | M19: =D19*L19 -> 0
A20: 11 | B20: Asphalt Binder Course | C20: ton | D20: 0 | E20: RD-02 | F20: =IF($E20="","",IFERROR(INDEX(MaterialPrices,MATCH($E20,MaterialCodes,0)),0)) -> 8500 | G20: 0 | H20: =IF($F20="",0,$F20*(1+$G20)) -> 8500 | I20: 0 | J20: 0 | K20: 0 | L20: =H20+I20+J20+K20 -> 8500 | M20: =D20*L20 -> 0
A21: 12 | B21: Asphalt Wearing Course | C21: ton | D21: 0 | E21: RD-02 | F21: =IF($E21="","",IFERROR(INDEX(MaterialPrices,MATCH($E21,MaterialCodes,0)),0)) -> 8500 | G21: 0 | H21: =IF($F21="",0,$F21*(1+$G21)) -> 8500 | I21: 0 | J21: 0 | K21: 0 | L21: =H21+I21+J21+K21 -> 8500 | M21: =D21*L21 -> 0
A22: Subtotal — C. PAVEMENT LAYERS | M22: =SUM(M16:M21) -> 0
A23: D. DRAINAGE & STRUCTURES
A24: 13 | B24: RC Pipe Culverts | C24: m | D24: 0 | E24: CONC-C25 | F24: =IF($E24="","",IFERROR(INDEX(MaterialPrices,MATCH($E24,MaterialCodes,0)),0)) -> 2296 | G24: ='Thresholds & Assumptions'!$B$53 -> 0.02 | H24: =IF($F24="",0,$F24*(1+$G24)) -> 2341.92 | I24: 0 | J24: 0 | K24: 0 | L24: =H24+I24+J24+K24 -> 2341.92 | M24: =D24*L24 -> 0
A25: 14 | B25: Roadside Drainage / French Drains | C25: m | D25: 0 | F25: =IF($E25="","",IFERROR(INDEX(MaterialPrices,MATCH($E25,MaterialCodes,0)),0)) | G25: 0 | H25: =IF($F25="",0,$F25*(1+$G25)) -> 0 | I25: 0 | J25: 0 | K25: 0 | L25: =H25+I25+J25+K25 -> 0 | M25: =D25*L25 -> 0
A26: 15 | B26: Manholes / Catch Basins | C26: No. | D26: 0 | E26: CONC-C25 | F26: =IF($E26="","",IFERROR(INDEX(MaterialPrices,MATCH($E26,MaterialCodes,0)),0)) -> 2296 | G26: ='Thresholds & Assumptions'!$B$53 -> 0.02 | H26: =IF($F26="",0,$F26*(1+$G26)) -> 2341.92 | I26: 0 | J26: 0 | K26: 0 | L26: =H26+I26+J26+K26 -> 2341.92 | M26: =D26*L26 -> 0
A27: Subtotal — D. DRAINAGE & STRUCTURES | M27: =SUM(M24:M26) -> 0
A28: E. ANCILLARY WORKS
A29: 16 | B29: Kerbstones | C29: m | D29: 0 | E29: CONC-C25 | F29: =IF($E29="","",IFERROR(INDEX(MaterialPrices,MATCH($E29,MaterialCodes,0)),0)) -> 2296 | G29: ='Thresholds & Assumptions'!$B$53 -> 0.02 | H29: =IF($F29="",0,$F29*(1+$G29)) -> 2341.92 | I29: 0 | J29: 0 | K29: 0 | L29: =H29+I29+J29+K29 -> 2341.92 | M29: =D29*L29 -> 0
A30: 17 | B30: Concrete Sidewalks | C30: m2 | D30: 0 | E30: CONC-C25 | F30: =IF($E30="","",IFERROR(INDEX(MaterialPrices,MATCH($E30,MaterialCodes,0)),0)) -> 2296 | G30: ='Thresholds & Assumptions'!$B$53 -> 0.02 | H30: =IF($F30="",0,$F30*(1+$G30)) -> 2341.92 | I30: 0 | J30: 0 | K30: 0 | L30: =H30+I30+J30+K30 -> 2341.92 | M30: =D30*L30 -> 0
A31: 18 | B31: Road Markings (Thermoplastic Paint) | C31: m2 | D31: 0 | F31: =IF($E31="","",IFERROR(INDEX(MaterialPrices,MATCH($E31,MaterialCodes,0)),0)) | G31: 0 | H31: =IF($F31="",0,$F31*(1+$G31)) -> 0 | I31: 0 | J31: 0 | K31: 0 | L31: =H31+I31+J31+K31 -> 0 | M31: =D31*L31 -> 0
A32: 19 | B32: Traffic Signs | C32: No. | D32: 0 | F32: =IF($E32="","",IFERROR(INDEX(MaterialPrices,MATCH($E32,MaterialCodes,0)),0)) | G32: 0 | H32: =IF($F32="",0,$F32*(1+$G32)) -> 0 | I32: 0 | J32: 0 | K32: 0 | L32: =H32+I32+J32+K32 -> 0 | M32: =D32*L32 -> 0
A33: 20 | B33: Guardrails / Safety Barriers | C33: m | D33: 0 | E33: STL-03 | F33: =IF($E33="","",IFERROR(INDEX(MaterialPrices,MATCH($E33,MaterialCodes,0)),0)) -> 45000 | G33: ='Thresholds & Assumptions'!$B$52 -> 0.03 | H33: =IF($F33="",0,$F33*(1+$G33)) -> 46350 | I33: 0 | J33: 0 | K33: 0 | L33: =H33+I33+J33+K33 -> 46350 | M33: =D33*L33 -> 0
A34: 21 | B34: Street Lighting | C34: No. | D34: 0 | F34: =IF($E34="","",IFERROR(INDEX(MaterialPrices,MATCH($E34,MaterialCodes,0)),0)) | G34: 0 | H34: =IF($F34="",0,$F34*(1+$G34)) -> 0 | I34: 0 | J34: 0 | K34: 0 | L34: =H34+I34+J34+K34 -> 0 | M34: =D34*L34 -> 0
A35: Subtotal — E. ANCILLARY WORKS | M35: =SUM(M29:M34) -> 0
A37: TOTAL DIRECT COST | M37: =M8+M14+M22+M27+M35 -> 0
A39: Total Road Length | D39: 1 | E39: km
A40: Indicative Direct Cost per km | D40: =IF(D39=0,0,M37/D39) -> 0

Sheet BOQ - Bridges
A1: BOQ - BRIDGES — BILL OF QUANTITIES & PRICING BUILD-UP
A2: Enter quantities and pick Material Codes from the dropdown — unit prices pull live from Fixed Material Prices
A4: Item | B4: Description | C4: Unit | D4: Quantity | E4: Material Code | F4: Material Unit Price (EGP) | G4: Wastage % | H4: Material Cost /Unit (EGP) | I4: Labor Cost /Unit (EGP) | J4: Equipment Cost /Unit (EGP) | K4: Subcontractor Rate/Unit (EGP) | L4: Direct Unit Rate (EGP) | M4: Amount (EGP) | N4: Notes
A5: A. PRELIMINARIES
A6: 1 | B6: Mobilization of Piling/Marine Equipment | C6: LS | D6: 0 | F6: =IF($E6="","",IFERROR(INDEX(MaterialPrices,MATCH($E6,MaterialCodes,0)),0)) | G6: 0 | H6: =IF($F6="",0,$F6*(1+$G6)) -> 0 | I6: 0 | J6: 0 | K6: 0 | L6: =H6+I6+J6+K6 -> 0 | M6: =D6*L6 -> 0
A7: 2 | B7: Temporary Works (Falsework/Staging) | C7: LS | D7: 0 | F7: =IF($E7="","",IFERROR(INDEX(MaterialPrices,MATCH($E7,MaterialCodes,0)),0)) | G7: 0 | H7: =IF($F7="",0,$F7*(1+$G7)) -> 0 | I7: 0 | J7: 0 | K7: 0 | L7: =H7+I7+J7+K7 -> 0 | M7: =D7*L7 -> 0
A8: Subtotal — A. PRELIMINARIES | M8: =SUM(M6:M7) -> 0
A9: B. SUBSTRUCTURE
A10: 3 | B10: Piling (Bored/Driven Piles) | C10: m | D10: 0 | E10: CONC-C30 | F10: =IF($E10="","",IFERROR(INDEX(MaterialPrices,MATCH($E10,MaterialCodes,0)),0)) -> 2387.5 | G10: ='Thresholds & Assumptions'!$B$53 -> 0.02 | H10: =IF($F10="",0,$F10*(1+$G10)) -> 2435.25 | I10: 0 | J10: 0 | K10: 0 | L10: =H10+I10+J10+K10 -> 2435.25 | M10: =D10*L10 -> 0
A11: 4 | B11: Pile Caps Concrete | C11: m3 | D11: 0 | E11: CONC-C30 | F11: =IF($E11="","",IFERROR(INDEX(MaterialPrices,MATCH($E11,MaterialCodes,0)),0)) -> 2387.5 | G11: ='Thresholds & Assumptions'!$B$53 -> 0.02 | H11: =IF($F11="",0,$F11*(1+$G11)) -> 2435.25 | I11: 0 | J11: 0 | K11: 0 | L11: =H11+I11+J11+K11 -> 2435.25 | M11: =D11*L11 -> 0
A12: 5 | B12: Pile Caps Reinforcement | C12: ton | D12: 0 | E12: STL-01 | F12: =IF($E12="","",IFERROR(INDEX(MaterialPrices,MATCH($E12,MaterialCodes,0)),0)) -> 36500 | G12: ='Thresholds & Assumptions'!$B$52 -> 0.03 | H12: =IF($F12="",0,$F12*(1+$G12)) -> 37595 | I12: 0 | J12: 0 | K12: 0 | L12: =H12+I12+J12+K12 -> 37595 | M12: =D12*L12 -> 0
A13: 6 | B13: Piers / Columns Concrete | C13: m3 | D13: 0 | E13: CONC-C35 | F13: =IF($E13="","",IFERROR(INDEX(MaterialPrices,MATCH($E13,MaterialCodes,0)),0)) -> 2445.5 | G13: ='Thresholds & Assumptions'!$B$53 -> 0.02 | H13: =IF($F13="",0,$F13*(1+$G13)) -> 2494.41 | I13: 0 | J13: 0 | K13: 0 | L13: =H13+I13+J13+K13 -> 2494.41 | M13: =D13*L13 -> 0
A14: 7 | B14: Piers / Columns Reinforcement | C14: ton | D14: 0 | E14: STL-01 | F14: =IF($E14="","",IFERROR(INDEX(MaterialPrices,MATCH($E14,MaterialCodes,0)),0)) -> 36500 | G14: ='Thresholds & Assumptions'!$B$52 -> 0.03 | H14: =IF($F14="",0,$F14*(1+$G14)) -> 37595 | I14: 0 | J14: 0 | K14: 0 | L14: =H14+I14+J14+K14 -> 37595 | M14: =D14*L14 -> 0
A15: 8 | B15: Abutments Concrete | C15: m3 | D15: 0 | E15: CONC-C30 | F15: =IF($E15="","",IFERROR(INDEX(MaterialPrices,MATCH($E15,MaterialCodes,0)),0)) -> 2387.5 | G15: ='Thresholds & Assumptions'!$B$53 -> 0.02 | H15: =IF($F15="",0,$F15*(1+$G15)) -> 2435.25 | I15: 0 | J15: 0 | K15: 0 | L15: =H15+I15+J15+K15 -> 2435.25 | M15: =D15*L15 -> 0
A16: 9 | B16: Abutments Reinforcement | C16: ton | D16: 0 | E16: STL-01 | F16: =IF($E16="","",IFERROR(INDEX(MaterialPrices,MATCH($E16,MaterialCodes,0)),0)) -> 36500 | G16: ='Thresholds & Assumptions'!$B$52 -> 0.03 | H16: =IF($F16="",0,$F16*(1+$G16)) -> 37595 | I16: 0 | J16: 0 | K16: 0 | L16: =H16+I16+J16+K16 -> 37595 | M16: =D16*L16 -> 0
A17: Subtotal — B. SUBSTRUCTURE | M17: =SUM(M10:M16) -> 0
A18: C. SUPERSTRUCTURE
A19: 10 | B19: Precast / Cast-in-situ Girders | C19: m3 | D19: 0 | E19: CONC-C40 | F19: =IF($E19="","",IFERROR(INDEX(MaterialPrices,MATCH($E19,MaterialCodes,0)),0)) -> 2522.5 | G19: ='Thresholds & Assumptions'!$B$53 -> 0.02 | H19: =IF($F19="",0,$F19*(1+$G19)) -> 2572.95 | I19: 0 | J19: 0 | K19: 0 | L19: =H19+I19+J19+K19 -> 2572.95 | M19: =D19*L19 -> 0
A20: 11 | B20: Deck Slab Concrete | C20: m3 | D20: 0 | E20: CONC-C35 | F20: =IF($E20="","",IFERROR(INDEX(MaterialPrices,MATCH($E20,MaterialCodes,0)),0)) -> 2445.5 | G20: ='Thresholds & Assumptions'!$B$53 -> 0.02 | H20: =IF($F20="",0,$F20*(1+$G20)) -> 2494.41 | I20: 0 | J20: 0 | K20: 0 | L20: =H20+I20+J20+K20 -> 2494.41 | M20: =D20*L20 -> 0
A21: 12 | B21: Deck Slab Reinforcement | C21: ton | D21: 0 | E21: STL-01 | F21: =IF($E21="","",IFERROR(INDEX(MaterialPrices,MATCH($E21,MaterialCodes,0)),0)) -> 36500 | G21: ='Thresholds & Assumptions'!$B$52 -> 0.03 | H21: =IF($F21="",0,$F21*(1+$G21)) -> 37595 | I21: 0 | J21: 0 | K21: 0 | L21: =H21+I21+J21+K21 -> 37595 | M21: =D21*L21 -> 0
A22: 13 | B22: Pre-stressing Works (Tendons/Strands) | C22: ton | D22: 0 | E22: STL-02 | F22: =IF($E22="","",IFERROR(INDEX(MaterialPrices,MATCH($E22,MaterialCodes,0)),0)) -> 39500 | G22: ='Thresholds & Assumptions'!$B$52 -> 0.03 | H22: =IF($F22="",0,$F22*(1+$G22)) -> 40685 | I22: 0 | J22: 0 | K22: 0 | L22: =H22+I22+J22+K22 -> 40685 | M22: =D22*L22 -> 0
A23: 14 | B23: Formwork/Falsework – Superstructure | C23: m2 | D23: 0 | E23: TBR-01 | F23: =IF($E23="","",IFERROR(INDEX(MaterialPrices,MATCH($E23,MaterialCodes,0)),0)) -> 900 | G23: ='Thresholds & Assumptions'!$B$57 -> 0.2 | H23: =IF($F23="",0,$F23*(1+$G23)) -> 1080 | I23: 0 | J23: 0 | K23: 0 | L23: =H23+I23+J23+K23 -> 1080 | M23: =D23*L23 -> 0
A24: Subtotal — C. SUPERSTRUCTURE | M24: =SUM(M19:M23) -> 0
A25: D. BRIDGE ACCESSORIES
A26: 15 | B26: Elastomeric Bearings | C26: No. | D26: 0 | E26: STL-03 | F26: =IF($E26="","",IFERROR(INDEX(MaterialPrices,MATCH($E26,MaterialCodes,0)),0)) -> 45000 | G26: ='Thresholds & Assumptions'!$B$52 -> 0.03 | H26: =IF($F26="",0,$F26*(1+$G26)) -> 46350 | I26: 0 | J26: 0 | K26: 0 | L26: =H26+I26+J26+K26 -> 46350 | M26: =D26*L26 -> 0
A27: 16 | B27: Expansion Joints | C27: m | D27: 0 | E27: STL-03 | F27: =IF($E27="","",IFERROR(INDEX(MaterialPrices,MATCH($E27,MaterialCodes,0)),0)) -> 45000 | G27: ='Thresholds & Assumptions'!$B$52 -> 0.03 | H27: =IF($F27="",0,$F27*(1+$G27)) -> 46350 | I27: 0 | J27: 0 | K27: 0 | L27: =H27+I27+J27+K27 -> 46350 | M27: =D27*L27 -> 0
A28: 17 | B28: Parapets / Railings | C28: m | D28: 0 | E28: STL-03 | F28: =IF($E28="","",IFERROR(INDEX(MaterialPrices,MATCH($E28,MaterialCodes,0)),0)) -> 45000 | G28: ='Thresholds & Assumptions'!$B$52 -> 0.03 | H28: =IF($F28="",0,$F28*(1+$G28)) -> 46350 | I28: 0 | J28: 0 | K28: 0 | L28: =H28+I28+J28+K28 -> 46350 | M28: =D28*L28 -> 0
A29: 18 | B29: Waterproofing of Deck | C29: m2 | D29: 0 | E29: WTP-01 | F29: =IF($E29="","",IFERROR(INDEX(MaterialPrices,MATCH($E29,MaterialCodes,0)),0)) -> 220 | G29: 0 | H29: =IF($F29="",0,$F29*(1+$G29)) -> 220 | I29: 0 | J29: 0 | K29: 0 | L29: =H29+I29+J29+K29 -> 220 | M29: =D29*L29 -> 0
A30: 19 | B30: Wearing Surface / Asphalt on Deck | C30: m2 | D30: 0 | E30: RD-02 | F30: =IF($E30="","",IFERROR(INDEX(MaterialPrices,MATCH($E30,MaterialCodes,0)),0)) -> 8500 | G30: 0 | H30: =IF($F30="",0,$F30*(1+$G30)) -> 8500 | I30: 0 | J30: 0 | K30: 0 | L30: =H30+I30+J30+K30 -> 8500 | M30: =D30*L30 -> 0
A31: 20 | B31: Drainage Scuppers / Downpipes | C31: No. | D31: 0 | F31: =IF($E31="","",IFERROR(INDEX(MaterialPrices,MATCH($E31,MaterialCodes,0)),0)) | G31: 0 | H31: =IF($F31="",0,$F31*(1+$G31)) -> 0 | I31: 0 | J31: 0 | K31: 0 | L31: =H31+I31+J31+K31 -> 0 | M31: =D31*L31 -> 0
A32: Subtotal — D. BRIDGE ACCESSORIES | M32: =SUM(M26:M31) -> 0
A33: E. APPROACH WORKS
A34: 21 | B34: Approach Slabs | C34: m3 | D34: 0 | E34: CONC-C30 | F34: =IF($E34="","",IFERROR(INDEX(MaterialPrices,MATCH($E34,MaterialCodes,0)),0)) -> 2387.5 | G34: ='Thresholds & Assumptions'!$B$53 -> 0.02 | H34: =IF($F34="",0,$F34*(1+$G34)) -> 2435.25 | I34: 0 | J34: 0 | K34: 0 | L34: =H34+I34+J34+K34 -> 2435.25 | M34: =D34*L34 -> 0
A35: 22 | B35: Approach Embankment | C35: m3 | D35: 0 | E35: AGG-01 | F35: =IF($E35="","",IFERROR(INDEX(MaterialPrices,MATCH($E35,MaterialCodes,0)),0)) -> 150 | G35: ='Thresholds & Assumptions'!$B$55 -> 0.05 | H35: =IF($F35="",0,$F35*(1+$G35)) -> 157.5 | I35: 0 | J35: 0 | K35: 0 | L35: =H35+I35+J35+K35 -> 157.5 | M35: =D35*L35 -> 0
A36: 23 | B36: Guardrails | C36: m | D36: 0 | E36: STL-03 | F36: =IF($E36="","",IFERROR(INDEX(MaterialPrices,MATCH($E36,MaterialCodes,0)),0)) -> 45000 | G36: ='Thresholds & Assumptions'!$B$52 -> 0.03 | H36: =IF($F36="",0,$F36*(1+$G36)) -> 46350 | I36: 0 | J36: 0 | K36: 0 | L36: =H36+I36+J36+K36 -> 46350 | M36: =D36*L36 -> 0
A37: Subtotal — E. APPROACH WORKS | M37: =SUM(M34:M36) -> 0
A39: TOTAL DIRECT COST | M39: =M8+M17+M24+M32+M37 -> 0
A41: Total Bridge Length | D41: 100 | E41: m
A42: Indicative Direct Cost per m | D42: =IF(D41=0,0,M39/D41) -> 0

Sheet BOQ - Tunnels
A1: BOQ - TUNNELS — BILL OF QUANTITIES & PRICING BUILD-UP
A2: Enter quantities and pick Material Codes from the dropdown — unit prices pull live from Fixed Material Prices
A4: Item | B4: Description | C4: Unit | D4: Quantity | E4: Material Code | F4: Material Unit Price (EGP) | G4: Wastage % | H4: Material Cost /Unit (EGP) | I4: Labor Cost /Unit (EGP) | J4: Equipment Cost /Unit (EGP) | K4: Subcontractor Rate/Unit (EGP) | L4: Direct Unit Rate (EGP) | M4: Amount (EGP) | N4: Notes
A5: A. PRELIMINARIES & SITE SETUP
A6: 1 | B6: Mobilization of Specialized TBM/NATM Equipment | C6: LS | D6: 0 | F6: =IF($E6="","",IFERROR(INDEX(MaterialPrices,MATCH($E6,MaterialCodes,0)),0)) | G6: 0 | H6: =IF($F6="",0,$F6*(1+$G6)) -> 0 | I6: 0 | J6: 0 | K6: 0 | L6: =H6+I6+J6+K6 -> 0 | M6: =D6*L6 -> 0
A7: 2 | B7: Site Investigation & Geotechnical Monitoring | C7: LS | D7: 0 | F7: =IF($E7="","",IFERROR(INDEX(MaterialPrices,MATCH($E7,MaterialCodes,0)),0)) | G7: 0 | H7: =IF($F7="",0,$F7*(1+$G7)) -> 0 | I7: 0 | J7: 0 | K7: 0 | L7: =H7+I7+J7+K7 -> 0 | M7: =D7*L7 -> 0
A8: Subtotal — A. PRELIMINARIES & SITE SETUP | M8: =SUM(M6:M7) -> 0
A9: B. PORTAL & APPROACH WORKS
A10: 3 | B10: Portal Excavation | C10: m3 | D10: 0 | F10: =IF($E10="","",IFERROR(INDEX(MaterialPrices,MATCH($E10,MaterialCodes,0)),0)) | G10: 0 | H10: =IF($F10="",0,$F10*(1+$G10)) -> 0 | I10: 0 | J10: 0 | K10: 0 | L10: =H10+I10+J10+K10 -> 0 | M10: =D10*L10 -> 0
A11: 4 | B11: Approach Cut & Retaining Structures | C11: m3 | D11: 0 | E11: CONC-C30 | F11: =IF($E11="","",IFERROR(INDEX(MaterialPrices,MATCH($E11,MaterialCodes,0)),0)) -> 2387.5 | G11: ='Thresholds & Assumptions'!$B$53 -> 0.02 | H11: =IF($F11="",0,$F11*(1+$G11)) -> 2435.25 | I11: 0 | J11: 0 | K11: 0 | L11: =H11+I11+J11+K11 -> 2435.25 | M11: =D11*L11 -> 0
A12: Subtotal — B. PORTAL & APPROACH WORKS | M12: =SUM(M10:M11) -> 0
A13: C. EXCAVATION & GROUND SUPPORT
A14: 5 | B14: Tunnel Excavation (NATM/Drill&Blast/TBM) | C14: m3 | D14: 0 | F14: =IF($E14="","",IFERROR(INDEX(MaterialPrices,MATCH($E14,MaterialCodes,0)),0)) | G14: 0 | H14: =IF($F14="",0,$F14*(1+$G14)) -> 0 | I14: 0 | J14: 0 | K14: 0 | L14: =H14+I14+J14+K14 -> 0 | M14: =D14*L14 -> 0
A15: 6 | B15: Shotcrete (Initial Lining) | C15: m3 | D15: 0 | E15: CONC-C30 | F15: =IF($E15="","",IFERROR(INDEX(MaterialPrices,MATCH($E15,MaterialCodes,0)),0)) -> 2387.5 | G15: ='Thresholds & Assumptions'!$B$53 -> 0.02 | H15: =IF($F15="",0,$F15*(1+$G15)) -> 2435.25 | I15: 0 | J15: 0 | K15: 0 | L15: =H15+I15+J15+K15 -> 2435.25 | M15: =D15*L15 -> 0
A16: 7 | B16: Steel Ribs / Lattice Girders | C16: ton | D16: 0 | E16: STL-03 | F16: =IF($E16="","",IFERROR(INDEX(MaterialPrices,MATCH($E16,MaterialCodes,0)),0)) -> 45000 | G16: ='Thresholds & Assumptions'!$B$52 -> 0.03 | H16: =IF($F16="",0,$F16*(1+$G16)) -> 46350 | I16: 0 | J16: 0 | K16: 0 | L16: =H16+I16+J16+K16 -> 46350 | M16: =D16*L16 -> 0
A17: 8 | B17: Rock Bolts / Soil Nails | C17: No. | D17: 0 | E17: STL-01 | F17: =IF($E17="","",IFERROR(INDEX(MaterialPrices,MATCH($E17,MaterialCodes,0)),0)) -> 36500 | G17: ='Thresholds & Assumptions'!$B$52 -> 0.03 | H17: =IF($F17="",0,$F17*(1+$G17)) -> 37595 | I17: 0 | J17: 0 | K17: 0 | L17: =H17+I17+J17+K17 -> 37595 | M17: =D17*L17 -> 0
A18: 9 | B18: Wire Mesh | C18: m2 | D18: 0 | E18: STL-01 | F18: =IF($E18="","",IFERROR(INDEX(MaterialPrices,MATCH($E18,MaterialCodes,0)),0)) -> 36500 | G18: ='Thresholds & Assumptions'!$B$52 -> 0.03 | H18: =IF($F18="",0,$F18*(1+$G18)) -> 37595 | I18: 0 | J18: 0 | K18: 0 | L18: =H18+I18+J18+K18 -> 37595 | M18: =D18*L18 -> 0
A19: 10 | B19: Grouting | C19: m3 | D19: 0 | E19: CEM-01 | F19: =IF($E19="","",IFERROR(INDEX(MaterialPrices,MATCH($E19,MaterialCodes,0)),0)) -> 3800 | G19: 0 | H19: =IF($F19="",0,$F19*(1+$G19)) -> 3800 | I19: 0 | J19: 0 | K19: 0 | L19: =H19+I19+J19+K19 -> 3800 | M19: =D19*L19 -> 0
A20: Subtotal — C. EXCAVATION & GROUND SUPPORT | M20: =SUM(M14:M19) -> 0
A21: D. PERMANENT LINING
A22: 11 | B22: Waterproofing Membrane | C22: m2 | D22: 0 | E22: WTP-01 | F22: =IF($E22="","",IFERROR(INDEX(MaterialPrices,MATCH($E22,MaterialCodes,0)),0)) -> 220 | G22: 0 | H22: =IF($F22="",0,$F22*(1+$G22)) -> 220 | I22: 0 | J22: 0 | K22: 0 | L22: =H22+I22+J22+K22 -> 220 | M22: =D22*L22 -> 0
A23: 12 | B23: Secondary Lining Concrete | C23: m3 | D23: 0 | E23: CONC-C35 | F23: =IF($E23="","",IFERROR(INDEX(MaterialPrices,MATCH($E23,MaterialCodes,0)),0)) -> 2445.5 | G23: ='Thresholds & Assumptions'!$B$53 -> 0.02 | H23: =IF($F23="",0,$F23*(1+$G23)) -> 2494.41 | I23: 0 | J23: 0 | K23: 0 | L23: =H23+I23+J23+K23 -> 2494.41 | M23: =D23*L23 -> 0
A24: 13 | B24: Reinforcement for Lining | C24: ton | D24: 0 | E24: STL-01 | F24: =IF($E24="","",IFERROR(INDEX(MaterialPrices,MATCH($E24,MaterialCodes,0)),0)) -> 36500 | G24: ='Thresholds & Assumptions'!$B$52 -> 0.03 | H24: =IF($F24="",0,$F24*(1+$G24)) -> 37595 | I24: 0 | J24: 0 | K24: 0 | L24: =H24+I24+J24+K24 -> 37595 | M24: =D24*L24 -> 0
A25: 14 | B25: Invert Concrete | C25: m3 | D25: 0 | E25: CONC-C30 | F25: =IF($E25="","",IFERROR(INDEX(MaterialPrices,MATCH($E25,MaterialCodes,0)),0)) -> 2387.5 | G25: ='Thresholds & Assumptions'!$B$53 -> 0.02 | H25: =IF($F25="",0,$F25*(1+$G25)) -> 2435.25 | I25: 0 | J25: 0 | K25: 0 | L25: =H25+I25+J25+K25 -> 2435.25 | M25: =D25*L25 -> 0
A26: Subtotal — D. PERMANENT LINING | M26: =SUM(M22:M25) -> 0
A27: E. MEP & SYSTEMS
A28: 15 | B28: Ventilation System | C28: LS | D28: 0 | F28: =IF($E28="","",IFERROR(INDEX(MaterialPrices,MATCH($E28,MaterialCodes,0)),0)) | G28: 0 | H28: =IF($F28="",0,$F28*(1+$G28)) -> 0 | I28: 0 | J28: 0 | K28: 0 | L28: =H28+I28+J28+K28 -> 0 | M28: =D28*L28 -> 0
A29: 16 | B29: Drainage System | C29: LS | D29: 0 | F29: =IF($E29="","",IFERROR(INDEX(MaterialPrices,MATCH($E29,MaterialCodes,0)),0)) | G29: 0 | H29: =IF($F29="",0,$F29*(1+$G29)) -> 0 | I29: 0 | J29: 0 | K29: 0 | L29: =H29+I29+J29+K29 -> 0 | M29: =D29*L29 -> 0
A30: 17 | B30: Lighting & Electrical | C30: LS | D30: 0 | F30: =IF($E30="","",IFERROR(INDEX(MaterialPrices,MATCH($E30,MaterialCodes,0)),0)) | G30: 0 | H30: =IF($F30="",0,$F30*(1+$G30)) -> 0 | I30: 0 | J30: 0 | K30: 0 | L30: =H30+I30+J30+K30 -> 0 | M30: =D30*L30 -> 0
A31: 18 | B31: Fire & Life Safety Systems | C31: LS | D31: 0 | F31: =IF($E31="","",IFERROR(INDEX(MaterialPrices,MATCH($E31,MaterialCodes,0)),0)) | G31: 0 | H31: =IF($F31="",0,$F31*(1+$G31)) -> 0 | I31: 0 | J31: 0 | K31: 0 | L31: =H31+I31+J31+K31 -> 0 | M31: =D31*L31 -> 0
A32: Subtotal — E. MEP & SYSTEMS | M32: =SUM(M28:M31) -> 0
A33: F. PORTAL FINISHING
A34: 19 | B34: Portal Architectural Finishes | C34: LS | D34: 0 | F34: =IF($E34="","",IFERROR(INDEX(MaterialPrices,MATCH($E34,MaterialCodes,0)),0)) | G34: 0 | H34: =IF($F34="",0,$F34*(1+$G34)) -> 0 | I34: 0 | J34: 0 | K34: 0 | L34: =H34+I34+J34+K34 -> 0 | M34: =D34*L34 -> 0
A35: Subtotal — F. PORTAL FINISHING | M35: =SUM(M34:M34) -> 0
A37: TOTAL DIRECT COST | M37: =M8+M12+M20+M26+M32+M35 -> 0
A39: Total Tunnel Length | D39: 500 | E39: m
A40: Indicative Direct Cost per m | D40: =IF(D39=0,0,M37/D39) -> 0

Sheet Bid Summary Dashboard
A1: BID SUMMARY DASHBOARD
A2: Consolidated bid build-up by scope, from Direct Cost to Grand Total Bid Price, with threshold checks
B4: Buildings | C4: Roads | D4: Bridges | E4: Tunnels | F4: Combined Total
A5: Include this scope in the bid? (Yes/No) | B5: Yes | C5: Yes | D5: Yes | E5: Yes
A6: Direct Cost (from BOQ) | B6: =IF(B5="Yes",'BOQ - Buildings'!$M$55,0) -> 0 | C6: =IF(C5="Yes",'BOQ - Roads'!$M$37,0) -> 0 | D6: =IF(D5="Yes",'BOQ - Bridges'!$M$39,0) -> 0 | E6: =IF(E5="Yes",'BOQ - Tunnels'!$M$37,0) -> 0 | F6: =SUM(B6:E6) -> 0
A7: Site (Field) Overhead % | B7: ='Thresholds & Assumptions'!$B$13 -> 0.1 | C7: ='Thresholds & Assumptions'!$B$13 -> 0.1 | D7: ='Thresholds & Assumptions'!$B$13 -> 0.1 | E7: ='Thresholds & Assumptions'!$B$13 -> 0.1
A8: Site Overhead Amount | B8: =B6*B7 -> 0 | C8: =C6*C7 -> 0 | D8: =D6*D7 -> 0 | E8: =E6*E7 -> 0 | F8: =SUM(B8:E8) -> 0
A9: Head Office Overhead % | B9: ='Thresholds & Assumptions'!$B$14 -> 0.06 | C9: ='Thresholds & Assumptions'!$B$14 -> 0.06 | D9: ='Thresholds & Assumptions'!$B$14 -> 0.06 | E9: ='Thresholds & Assumptions'!$B$14 -> 0.06
A10: Head Office Overhead Amount | B10: =B6*B9 -> 0 | C10: =C6*C9 -> 0 | D10: =D6*D9 -> 0 | E10: =E6*E9 -> 0 | F10: =SUM(B10:E10) -> 0
A11: Subtotal after Overheads | B11: =B6+B8+B10 -> 0 | C11: =C6+C8+C10 -> 0 | D11: =D6+D8+D10 -> 0 | E11: =E6+E8+E10 -> 0 | F11: =SUM(B11:E11) -> 0
A12: Risk Level | B12: Medium | C12: Medium | D12: Medium | E12: Medium
A13: Contingency % | B13: =IFERROR(INDEX('Thresholds & Assumptions'!$A$6:$B$9,MATCH(B12,'Thresholds & Assumptions'!$A$6:$A$9,0),2),0) -> 0.06 | C13: =IFERROR(INDEX('Thresholds & Assumptions'!$A$6:$B$9,MATCH(C12,'Thresholds & Assumptions'!$A$6:$A$9,0),2),0) -> 0.06 | D13: =IFERROR(INDEX('Thresholds & Assumptions'!$A$6:$B$9,MATCH(D12,'Thresholds & Assumptions'!$A$6:$A$9,0),2),0) -> 0.06 | E13: =IFERROR(INDEX('Thresholds & Assumptions'!$A$6:$B$9,MATCH(E12,'Thresholds & Assumptions'!$A$6:$A$9,0),2),0) -> 0.06
A14: Contingency Amount | B14: =B11*B13 -> 0 | C14: =C11*C13 -> 0 | D14: =D11*D13 -> 0 | E14: =E11*E13 -> 0 | F14: =SUM(B14:E14) -> 0
A15: Price Escalation % | B15: ='Thresholds & Assumptions'!$B$27 -> 0.075 | C15: ='Thresholds & Assumptions'!$B$27 -> 0.075 | D15: ='Thresholds & Assumptions'!$B$27 -> 0.075 | E15: ='Thresholds & Assumptions'!$B$27 -> 0.075
A16: Escalation Amount | B16: =B11*B15 -> 0 | C16: =C11*C15 -> 0 | D16: =D11*D15 -> 0 | E16: =E11*E15 -> 0 | F16: =SUM(B16:E16) -> 0
A17: Subtotal before Profit | B17: =B11+B14+B16 -> 0 | C17: =C11+C14+C16 -> 0 | D17: =D11+D14+D16 -> 0 | E17: =E11+E14+E16 -> 0 | F17: =SUM(B17:E17) -> 0
A18: Profit Margin % Applied | B18: ='Thresholds & Assumptions'!$C$18 -> 0.1 | C18: ='Thresholds & Assumptions'!$C$19 -> 0.08 | D18: ='Thresholds & Assumptions'!$C$20 -> 0.12 | E18: ='Thresholds & Assumptions'!$C$21 -> 0.15
A19: Profit Amount | B19: =B17*B18 -> 0 | C19: =C17*C18 -> 0 | D19: =D17*D18 -> 0 | E19: =E17*E18 -> 0 | F19: =SUM(B19:E19) -> 0
A20: Subtotal – Net Bid Price before Bonds/Insurance/VAT | B20: =B17+B19 -> 0 | C20: =C17+C19 -> 0 | D20: =D17+D19 -> 0 | E20: =E17+E19 -> 0 | F20: =SUM(B20:E20) -> 0
A21: Bonds, Guarantees & Insurance % | B21: ='Thresholds & Assumptions'!$B$36*('Thresholds & Assumptions'!$B$32+'Thresholds & Assumptions'!$B$34)+'Thresholds & Assumptions'!$B$40+'Thresholds & Assumptions'!$B$41 -> 0.0095 | C21: ='Thresholds & Assumptions'!$B$36*('Thresholds & Assumptions'!$B$32+'Thresholds & Assumptions'!$B$34)+'Thresholds & Assumptions'!$B$40+'Thresholds & Assumptions'!$B$41 -> 0.0095 | D21: ='Thresholds & Assumptions'!$B$36*('Thresholds & Assumptions'!$B$32+'Thresholds & Assumptions'!$B$34)+'Thresholds & Assumptions'!$B$40+'Thresholds & Assumptions'!$B$41 -> 0.0095 | E21: ='Thresholds & Assumptions'!$B$36*('Thresholds & Assumptions'!$B$32+'Thresholds & Assumptions'!$B$34)+'Thresholds & Assumptions'!$B$40+'Thresholds & Assumptions'!$B$41 -> 0.0095
A22: Bonds & Insurance Amount | B22: =B20*B21 -> 0 | C22: =C20*C21 -> 0 | D22: =D20*D21 -> 0 | E22: =E20*E21 -> 0 | F22: =SUM(B22:E22) -> 0
A23: Financing / Working-Capital Cost % | B23: ='Thresholds & Assumptions'!$B$64 -> 0.036164384 | C23: ='Thresholds & Assumptions'!$B$64 -> 0.036164384 | D23: ='Thresholds & Assumptions'!$B$64 -> 0.036164384 | E23: ='Thresholds & Assumptions'!$B$64 -> 0.036164384
A24: Financing Cost Amount | B24: =B20*B23 -> 0 | C24: =C20*C23 -> 0 | D24: =D20*D23 -> 0 | E24: =E20*E23 -> 0 | F24: =SUM(B24:E24) -> 0
A25: Price before VAT | B25: =B20+B22+B24 -> 0 | C25: =C20+C22+C24 -> 0 | D25: =D20+D22+D24 -> 0 | E25: =E20+E22+E24 -> 0 | F25: =SUM(B25:E25) -> 0
A26: VAT % | B26: ='Thresholds & Assumptions'!$B$46 -> 0.14 | C26: ='Thresholds & Assumptions'!$B$46 -> 0.14 | D26: ='Thresholds & Assumptions'!$B$46 -> 0.14 | E26: ='Thresholds & Assumptions'!$B$46 -> 0.14
A27: VAT Amount | B27: =B25*B26 -> 0 | C27: =C25*C26 -> 0 | D27: =D25*D26 -> 0 | E27: =E25*E26 -> 0 | F27: =SUM(B27:E27) -> 0
A28: GRAND TOTAL BID PRICE (EGP) | B28: =B25+B27 -> 0 | C28: =C25+C27 -> 0 | D28: =D25+D27 -> 0 | E28: =E25+E27 -> 0 | F28: =SUM(B28:E28) -> 0
A30: Reference Quantity (from BOQ) | B30: ='BOQ - Buildings'!$D$57 -> 1000 | C30: ='BOQ - Roads'!$D$39 -> 1 | D30: ='BOQ - Bridges'!$D$41 -> 100 | E30: ='BOQ - Tunnels'!$D$39 -> 500
A31: Bid Price per Unit (EGP) | B31: =IF(B30=0,0,B28/B30) -> 0 | C31: =IF(C30=0,0,C28/C30) -> 0 | D31: =IF(D30=0,0,D28/D30) -> 0 | E31: =IF(E30=0,0,E28/E30) -> 0
